*** Starting uWSGI 2.0.23 (64bit) on [Sun Jan 28 10:10:15 2024] ***
compiled with version: 7.5.0 on 28 January 2024 01:25:38
os: Linux-5.4.0-150-generic #167~18.04.1-Ubuntu SMP Wed May 24 00:51:42 UTC 2023
nodename: lz-virtual-machine
machine: x86_64
clock source: unix
detected number of CPU cores: 2
current working directory: /home/lz/demo/network/python/web
writing pidfile to uwsgi.pidfile
detected binary path: /usr/local/bin/uwsgi
!!! no internal routing support, rebuild with pcre support !!!
chdir() to /demo/network/python/web
chdir(): No such file or directory [core/uwsgi.c line 2628]
*** Starting uWSGI 2.0.23 (64bit) on [Sun Jan 28 10:12:50 2024] ***
compiled with version: 7.5.0 on 28 January 2024 01:25:38
os: Linux-5.4.0-150-generic #167~18.04.1-Ubuntu SMP Wed May 24 00:51:42 UTC 2023
nodename: lz-virtual-machine
machine: x86_64
clock source: unix
detected number of CPU cores: 2
current working directory: /home/lz/demo/network/python/web
writing pidfile to uwsgi.pidfile
detected binary path: /usr/local/bin/uwsgi
!!! no internal routing support, rebuild with pcre support !!!
chdir() to /demo/network/python/web
chdir(): No such file or directory [core/uwsgi.c line 2628]
*** Starting uWSGI 2.0.23 (64bit) on [Sun Jan 28 10:24:05 2024] ***
compiled with version: 7.5.0 on 28 January 2024 01:25:38
os: Linux-5.4.0-150-generic #167~18.04.1-Ubuntu SMP Wed May 24 00:51:42 UTC 2023
nodename: lz-virtual-machine
machine: x86_64
clock source: unix
detected number of CPU cores: 2
current working directory: /home/lz/demo/network/python/web
writing pidfile to uwsgi.pidfile
detected binary path: /usr/local/bin/uwsgi
!!! no internal routing support, rebuild with pcre support !!!
chdir() to /demo/network/python/web
chdir(): No such file or directory [core/uwsgi.c line 2628]
*** Starting uWSGI 2.0.23 (64bit) on [Sun Jan 28 10:25:37 2024] ***
compiled with version: 7.5.0 on 28 January 2024 01:25:38
os: Linux-5.4.0-150-generic #167~18.04.1-Ubuntu SMP Wed May 24 00:51:42 UTC 2023
nodename: lz-virtual-machine
machine: x86_64
clock source: unix
detected number of CPU cores: 2
current working directory: /home/lz/demo/network/python/web
writing pidfile to uwsgi.pidfile
detected binary path: /usr/local/bin/uwsgi
!!! no internal routing support, rebuild with pcre support !!!
chdir() to /home/lz/demo/network/python/web
your processes number limit is 15400
your memory page size is 4096 bytes
detected max file descriptor number: 1048576
lock engine: pthread robust mutexes
thunder lock: disabled (you can enable it with --thunder-lock)
uWSGI http bound on 192.168.1.7:8000 fd 4
uwsgi socket 0 bound to TCP address 127.0.0.1:34557 (port auto-assigned) fd 3
Python version: 2.7.17 (default, Mar  8 2023, 18:40:28)  [GCC 7.5.0]
Python main interpreter initialized at 0x561245be13e0
python threads support enabled
your server socket listen backlog is limited to 100 connections
your mercy for graceful operations on workers is 60 seconds
mapped 203152 bytes (198 KB) for 1 cores
*** Operational MODE: single process ***
*** uWSGI is running in multiple interpreter mode ***
spawned uWSGI master process (pid: 9969)
spawned uWSGI worker 1 (pid: 9971, cores: 1)
spawned uWSGI http 1 (pid: 9972)
WSGI app 0 (mountpoint='') ready in 0 seconds on interpreter 0x561245be13e0 pid: 9971 (default app)
Traceback (most recent call last):
  File "/usr/local/lib/python2.7/dist-packages/web/application.py", line 290, in process
    return self.handle()
  File "/usr/local/lib/python2.7/dist-packages/web/application.py", line 281, in handle
    return self._delegate(fn, self.fvars, args)
  File "/usr/local/lib/python2.7/dist-packages/web/application.py", line 531, in _delegate
    return handle_class(cls)
  File "/usr/local/lib/python2.7/dist-packages/web/application.py", line 509, in handle_class
    return tocall(*args)
TypeError: GET() takes exactly 2 arguments (1 given)

Traceback (most recent call last):
  File "/usr/local/lib/python2.7/dist-packages/web/application.py", line 288, in process
    return p(lambda: process(processors))
  File "/usr/local/lib/python2.7/dist-packages/web/application.py", line 700, in processor
    return handler()
  File "/usr/local/lib/python2.7/dist-packages/web/application.py", line 288, in <lambda>
    return p(lambda: process(processors))
  File "/usr/local/lib/python2.7/dist-packages/web/application.py", line 297, in process
    raise self.internalerror()
  File "/usr/local/lib/python2.7/dist-packages/web/application.py", line 588, in internalerror
    return debugerror()
  File "/usr/local/lib/python2.7/dist-packages/web/debugerror.py", line 337, in debugerror
    return web._InternalError(djangoerror())
  File "/usr/local/lib/python2.7/dist-packages/web/debugerror.py", line 315, in djangoerror
    djangoerror_r = Template(djangoerror_t, filename=__file__, filter=websafe)
  File "/usr/local/lib/python2.7/dist-packages/web/template.py", line 943, in __init__
    code = self.compile_template(text, filename)
  File "/usr/local/lib/python2.7/dist-packages/web/template.py", line 1020, in compile_template
    compiled_code = compile(code, filename, "exec")
  File "/usr/local/lib/python2.7/dist-packages/web/debugerror.pyc", line 8
    def with (exception_type, exception_value, frames)
           ^
SyntaxError: invalid syntax

Traceback (most recent call last):
  File "/usr/local/lib/python2.7/dist-packages/web/application.py", line 288, in process
    return p(lambda: process(processors))
  File "/usr/local/lib/python2.7/dist-packages/web/application.py", line 700, in processor
    return handler()
  File "/usr/local/lib/python2.7/dist-packages/web/application.py", line 288, in <lambda>
    return p(lambda: process(processors))
  File "/usr/local/lib/python2.7/dist-packages/web/application.py", line 297, in process
    raise self.internalerror()
  File "/usr/local/lib/python2.7/dist-packages/web/application.py", line 588, in internalerror
    return debugerror()
  File "/usr/local/lib/python2.7/dist-packages/web/debugerror.py", line 337, in debugerror
    return web._InternalError(djangoerror())
  File "/usr/local/lib/python2.7/dist-packages/web/debugerror.py", line 315, in djangoerror
    djangoerror_r = Template(djangoerror_t, filename=__file__, filter=websafe)
  File "/usr/local/lib/python2.7/dist-packages/web/template.py", line 943, in __init__
    code = self.compile_template(text, filename)
  File "/usr/local/lib/python2.7/dist-packages/web/template.py", line 1020, in compile_template
    compiled_code = compile(code, filename, "exec")
  File "/usr/local/lib/python2.7/dist-packages/web/debugerror.pyc", line 8
    def with (exception_type, exception_value, frames)
           ^
SyntaxError: invalid syntax

Traceback (most recent call last):
  File "/usr/local/lib/python2.7/dist-packages/web/application.py", line 288, in process
    return p(lambda: process(processors))
  File "/usr/local/lib/python2.7/dist-packages/web/application.py", line 717, in processor
    result = handler()
  File "/usr/local/lib/python2.7/dist-packages/web/application.py", line 288, in <lambda>
    return p(lambda: process(processors))
  File "/usr/local/lib/python2.7/dist-packages/web/application.py", line 297, in process
    raise self.internalerror()
  File "/usr/local/lib/python2.7/dist-packages/web/application.py", line 588, in internalerror
    return debugerror()
  File "/usr/local/lib/python2.7/dist-packages/web/debugerror.py", line 337, in debugerror
    return web._InternalError(djangoerror())
  File "/usr/local/lib/python2.7/dist-packages/web/debugerror.py", line 315, in djangoerror
    djangoerror_r = Template(djangoerror_t, filename=__file__, filter=websafe)
  File "/usr/local/lib/python2.7/dist-packages/web/template.py", line 943, in __init__
    code = self.compile_template(text, filename)
  File "/usr/local/lib/python2.7/dist-packages/web/template.py", line 1020, in compile_template
    compiled_code = compile(code, filename, "exec")
  File "/usr/local/lib/python2.7/dist-packages/web/debugerror.pyc", line 8
    def with (exception_type, exception_value, frames)
           ^
SyntaxError: invalid syntax

Traceback (most recent call last):
  File "/usr/local/lib/python2.7/dist-packages/web/application.py", line 288, in process
    return p(lambda: process(processors))
  File "/usr/local/lib/python2.7/dist-packages/web/application.py", line 700, in processor
    return handler()
  File "/usr/local/lib/python2.7/dist-packages/web/application.py", line 288, in <lambda>
    return p(lambda: process(processors))
  File "/usr/local/lib/python2.7/dist-packages/web/application.py", line 297, in process
    raise self.internalerror()
  File "/usr/local/lib/python2.7/dist-packages/web/application.py", line 588, in internalerror
    return debugerror()
  File "/usr/local/lib/python2.7/dist-packages/web/debugerror.py", line 337, in debugerror
    return web._InternalError(djangoerror())
  File "/usr/local/lib/python2.7/dist-packages/web/debugerror.py", line 315, in djangoerror
    djangoerror_r = Template(djangoerror_t, filename=__file__, filter=websafe)
  File "/usr/local/lib/python2.7/dist-packages/web/template.py", line 943, in __init__
    code = self.compile_template(text, filename)
  File "/usr/local/lib/python2.7/dist-packages/web/template.py", line 1020, in compile_template
    compiled_code = compile(code, filename, "exec")
  File "/usr/local/lib/python2.7/dist-packages/web/debugerror.pyc", line 8
    def with (exception_type, exception_value, frames)
           ^
SyntaxError: invalid syntax

Traceback (most recent call last):
  File "/usr/local/lib/python2.7/dist-packages/web/application.py", line 329, in wsgi
    result = self.handle_with_processors()
  File "/usr/local/lib/python2.7/dist-packages/web/application.py", line 300, in handle_with_processors
    return process(self.processors)
  File "/usr/local/lib/python2.7/dist-packages/web/application.py", line 297, in process
    raise self.internalerror()
  File "/usr/local/lib/python2.7/dist-packages/web/application.py", line 588, in internalerror
    return debugerror()
  File "/usr/local/lib/python2.7/dist-packages/web/debugerror.py", line 337, in debugerror
    return web._InternalError(djangoerror())
  File "/usr/local/lib/python2.7/dist-packages/web/debugerror.py", line 315, in djangoerror
    djangoerror_r = Template(djangoerror_t, filename=__file__, filter=websafe)
  File "/usr/local/lib/python2.7/dist-packages/web/template.py", line 943, in __init__
    code = self.compile_template(text, filename)
  File "/usr/local/lib/python2.7/dist-packages/web/template.py", line 1020, in compile_template
    compiled_code = compile(code, filename, "exec")
  File "/usr/local/lib/python2.7/dist-packages/web/debugerror.pyc", line 8
    def with (exception_type, exception_value, frames)
           ^
SyntaxError: invalid syntax

Template traceback:
    File '/usr/local/lib/python2.7/dist-packages/web/debugerror.pyc', line 8
        None
[pid: 9971|app: 0|req: 1/1] 192.168.1.29 () {38 vars in 754 bytes} [Sun Jan 28 10:25:46 2024] GET / => generated 0 bytes in 61 msecs (HTTP/1.1 500) 0 headers in 0 bytes (0 switches on core 0)
Traceback (most recent call last):
  File "/usr/local/lib/python2.7/dist-packages/web/application.py", line 290, in process
    return self.handle()
  File "/usr/local/lib/python2.7/dist-packages/web/application.py", line 281, in handle
    return self._delegate(fn, self.fvars, args)
  File "/usr/local/lib/python2.7/dist-packages/web/application.py", line 531, in _delegate
    return handle_class(cls)
  File "/usr/local/lib/python2.7/dist-packages/web/application.py", line 509, in handle_class
    return tocall(*args)
TypeError: GET() takes exactly 2 arguments (1 given)

Traceback (most recent call last):
  File "/usr/local/lib/python2.7/dist-packages/web/application.py", line 288, in process
    return p(lambda: process(processors))
  File "/usr/local/lib/python2.7/dist-packages/web/application.py", line 700, in processor
    return handler()
  File "/usr/local/lib/python2.7/dist-packages/web/application.py", line 288, in <lambda>
    return p(lambda: process(processors))
  File "/usr/local/lib/python2.7/dist-packages/web/application.py", line 297, in process
    raise self.internalerror()
  File "/usr/local/lib/python2.7/dist-packages/web/application.py", line 588, in internalerror
    return debugerror()
  File "/usr/local/lib/python2.7/dist-packages/web/debugerror.py", line 337, in debugerror
    return web._InternalError(djangoerror())
  File "/usr/local/lib/python2.7/dist-packages/web/debugerror.py", line 315, in djangoerror
    djangoerror_r = Template(djangoerror_t, filename=__file__, filter=websafe)
  File "/usr/local/lib/python2.7/dist-packages/web/template.py", line 943, in __init__
    code = self.compile_template(text, filename)
  File "/usr/local/lib/python2.7/dist-packages/web/template.py", line 1020, in compile_template
    compiled_code = compile(code, filename, "exec")
  File "/usr/local/lib/python2.7/dist-packages/web/debugerror.pyc", line 8
    def with (exception_type, exception_value, frames)
           ^
SyntaxError: invalid syntax

Traceback (most recent call last):
  File "/usr/local/lib/python2.7/dist-packages/web/application.py", line 288, in process
    return p(lambda: process(processors))
  File "/usr/local/lib/python2.7/dist-packages/web/application.py", line 700, in processor
    return handler()
  File "/usr/local/lib/python2.7/dist-packages/web/application.py", line 288, in <lambda>
    return p(lambda: process(processors))
  File "/usr/local/lib/python2.7/dist-packages/web/application.py", line 297, in process
    raise self.internalerror()
  File "/usr/local/lib/python2.7/dist-packages/web/application.py", line 588, in internalerror
    return debugerror()
  File "/usr/local/lib/python2.7/dist-packages/web/debugerror.py", line 337, in debugerror
    return web._InternalError(djangoerror())
  File "/usr/local/lib/python2.7/dist-packages/web/debugerror.py", line 315, in djangoerror
    djangoerror_r = Template(djangoerror_t, filename=__file__, filter=websafe)
  File "/usr/local/lib/python2.7/dist-packages/web/template.py", line 943, in __init__
    code = self.compile_template(text, filename)
  File "/usr/local/lib/python2.7/dist-packages/web/template.py", line 1020, in compile_template
    compiled_code = compile(code, filename, "exec")
  File "/usr/local/lib/python2.7/dist-packages/web/debugerror.pyc", line 8
    def with (exception_type, exception_value, frames)
           ^
SyntaxError: invalid syntax

Traceback (most recent call last):
  File "/usr/local/lib/python2.7/dist-packages/web/application.py", line 288, in process
    return p(lambda: process(processors))
  File "/usr/local/lib/python2.7/dist-packages/web/application.py", line 717, in processor
    result = handler()
  File "/usr/local/lib/python2.7/dist-packages/web/application.py", line 288, in <lambda>
    return p(lambda: process(processors))
  File "/usr/local/lib/python2.7/dist-packages/web/application.py", line 297, in process
    raise self.internalerror()
  File "/usr/local/lib/python2.7/dist-packages/web/application.py", line 588, in internalerror
    return debugerror()
  File "/usr/local/lib/python2.7/dist-packages/web/debugerror.py", line 337, in debugerror
    return web._InternalError(djangoerror())
  File "/usr/local/lib/python2.7/dist-packages/web/debugerror.py", line 315, in djangoerror
    djangoerror_r = Template(djangoerror_t, filename=__file__, filter=websafe)
  File "/usr/local/lib/python2.7/dist-packages/web/template.py", line 943, in __init__
    code = self.compile_template(text, filename)
  File "/usr/local/lib/python2.7/dist-packages/web/template.py", line 1020, in compile_template
    compiled_code = compile(code, filename, "exec")
  File "/usr/local/lib/python2.7/dist-packages/web/debugerror.pyc", line 8
    def with (exception_type, exception_value, frames)
           ^
SyntaxError: invalid syntax

Traceback (most recent call last):
  File "/usr/local/lib/python2.7/dist-packages/web/application.py", line 288, in process
    return p(lambda: process(processors))
  File "/usr/local/lib/python2.7/dist-packages/web/application.py", line 700, in processor
    return handler()
  File "/usr/local/lib/python2.7/dist-packages/web/application.py", line 288, in <lambda>
    return p(lambda: process(processors))
  File "/usr/local/lib/python2.7/dist-packages/web/application.py", line 297, in process
    raise self.internalerror()
  File "/usr/local/lib/python2.7/dist-packages/web/application.py", line 588, in internalerror
    return debugerror()
  File "/usr/local/lib/python2.7/dist-packages/web/debugerror.py", line 337, in debugerror
    return web._InternalError(djangoerror())
  File "/usr/local/lib/python2.7/dist-packages/web/debugerror.py", line 315, in djangoerror
    djangoerror_r = Template(djangoerror_t, filename=__file__, filter=websafe)
  File "/usr/local/lib/python2.7/dist-packages/web/template.py", line 943, in __init__
    code = self.compile_template(text, filename)
  File "/usr/local/lib/python2.7/dist-packages/web/template.py", line 1020, in compile_template
    compiled_code = compile(code, filename, "exec")
  File "/usr/local/lib/python2.7/dist-packages/web/debugerror.pyc", line 8
    def with (exception_type, exception_value, frames)
           ^
SyntaxError: invalid syntax

Traceback (most recent call last):
  File "/usr/local/lib/python2.7/dist-packages/web/application.py", line 329, in wsgi
    result = self.handle_with_processors()
  File "/usr/local/lib/python2.7/dist-packages/web/application.py", line 300, in handle_with_processors
    return process(self.processors)
  File "/usr/local/lib/python2.7/dist-packages/web/application.py", line 297, in process
    raise self.internalerror()
  File "/usr/local/lib/python2.7/dist-packages/web/application.py", line 588, in internalerror
    return debugerror()
  File "/usr/local/lib/python2.7/dist-packages/web/debugerror.py", line 337, in debugerror
    return web._InternalError(djangoerror())
  File "/usr/local/lib/python2.7/dist-packages/web/debugerror.py", line 315, in djangoerror
    djangoerror_r = Template(djangoerror_t, filename=__file__, filter=websafe)
  File "/usr/local/lib/python2.7/dist-packages/web/template.py", line 943, in __init__
    code = self.compile_template(text, filename)
  File "/usr/local/lib/python2.7/dist-packages/web/template.py", line 1020, in compile_template
    compiled_code = compile(code, filename, "exec")
  File "/usr/local/lib/python2.7/dist-packages/web/debugerror.pyc", line 8
    def with (exception_type, exception_value, frames)
           ^
SyntaxError: invalid syntax

Template traceback:
    File '/usr/local/lib/python2.7/dist-packages/web/debugerror.pyc', line 8
        None
[pid: 9971|app: 0|req: 2/2] 192.168.1.29 () {38 vars in 754 bytes} [Sun Jan 28 10:25:46 2024] GET / => generated 0 bytes in 33 msecs (HTTP/1.1 500) 0 headers in 0 bytes (0 switches on core 0)
Traceback (most recent call last):
  File "/usr/local/lib/python2.7/dist-packages/web/application.py", line 290, in process
    return self.handle()
  File "/usr/local/lib/python2.7/dist-packages/web/application.py", line 281, in handle
    return self._delegate(fn, self.fvars, args)
  File "/usr/local/lib/python2.7/dist-packages/web/application.py", line 531, in _delegate
    return handle_class(cls)
  File "/usr/local/lib/python2.7/dist-packages/web/application.py", line 509, in handle_class
    return tocall(*args)
TypeError: GET() takes exactly 2 arguments (1 given)

Traceback (most recent call last):
  File "/usr/local/lib/python2.7/dist-packages/web/application.py", line 288, in process
    return p(lambda: process(processors))
  File "/usr/local/lib/python2.7/dist-packages/web/application.py", line 700, in processor
    return handler()
  File "/usr/local/lib/python2.7/dist-packages/web/application.py", line 288, in <lambda>
    return p(lambda: process(processors))
  File "/usr/local/lib/python2.7/dist-packages/web/application.py", line 297, in process
    raise self.internalerror()
  File "/usr/local/lib/python2.7/dist-packages/web/application.py", line 588, in internalerror
    return debugerror()
  File "/usr/local/lib/python2.7/dist-packages/web/debugerror.py", line 337, in debugerror
    return web._InternalError(djangoerror())
  File "/usr/local/lib/python2.7/dist-packages/web/debugerror.py", line 315, in djangoerror
    djangoerror_r = Template(djangoerror_t, filename=__file__, filter=websafe)
  File "/usr/local/lib/python2.7/dist-packages/web/template.py", line 943, in __init__
    code = self.compile_template(text, filename)
  File "/usr/local/lib/python2.7/dist-packages/web/template.py", line 1020, in compile_template
    compiled_code = compile(code, filename, "exec")
  File "/usr/local/lib/python2.7/dist-packages/web/debugerror.pyc", line 8
    def with (exception_type, exception_value, frames)
           ^
SyntaxError: invalid syntax

Traceback (most recent call last):
  File "/usr/local/lib/python2.7/dist-packages/web/application.py", line 288, in process
    return p(lambda: process(processors))
  File "/usr/local/lib/python2.7/dist-packages/web/application.py", line 700, in processor
    return handler()
  File "/usr/local/lib/python2.7/dist-packages/web/application.py", line 288, in <lambda>
    return p(lambda: process(processors))
  File "/usr/local/lib/python2.7/dist-packages/web/application.py", line 297, in process
    raise self.internalerror()
  File "/usr/local/lib/python2.7/dist-packages/web/application.py", line 588, in internalerror
    return debugerror()
  File "/usr/local/lib/python2.7/dist-packages/web/debugerror.py", line 337, in debugerror
    return web._InternalError(djangoerror())
  File "/usr/local/lib/python2.7/dist-packages/web/debugerror.py", line 315, in djangoerror
    djangoerror_r = Template(djangoerror_t, filename=__file__, filter=websafe)
  File "/usr/local/lib/python2.7/dist-packages/web/template.py", line 943, in __init__
    code = self.compile_template(text, filename)
  File "/usr/local/lib/python2.7/dist-packages/web/template.py", line 1020, in compile_template
    compiled_code = compile(code, filename, "exec")
  File "/usr/local/lib/python2.7/dist-packages/web/debugerror.pyc", line 8
    def with (exception_type, exception_value, frames)
           ^
SyntaxError: invalid syntax

Traceback (most recent call last):
  File "/usr/local/lib/python2.7/dist-packages/web/application.py", line 288, in process
    return p(lambda: process(processors))
  File "/usr/local/lib/python2.7/dist-packages/web/application.py", line 717, in processor
    result = handler()
  File "/usr/local/lib/python2.7/dist-packages/web/application.py", line 288, in <lambda>
    return p(lambda: process(processors))
  File "/usr/local/lib/python2.7/dist-packages/web/application.py", line 297, in process
    raise self.internalerror()
  File "/usr/local/lib/python2.7/dist-packages/web/application.py", line 588, in internalerror
    return debugerror()
  File "/usr/local/lib/python2.7/dist-packages/web/debugerror.py", line 337, in debugerror
    return web._InternalError(djangoerror())
  File "/usr/local/lib/python2.7/dist-packages/web/debugerror.py", line 315, in djangoerror
    djangoerror_r = Template(djangoerror_t, filename=__file__, filter=websafe)
  File "/usr/local/lib/python2.7/dist-packages/web/template.py", line 943, in __init__
    code = self.compile_template(text, filename)
  File "/usr/local/lib/python2.7/dist-packages/web/template.py", line 1020, in compile_template
    compiled_code = compile(code, filename, "exec")
  File "/usr/local/lib/python2.7/dist-packages/web/debugerror.pyc", line 8
    def with (exception_type, exception_value, frames)
           ^
SyntaxError: invalid syntax

Traceback (most recent call last):
  File "/usr/local/lib/python2.7/dist-packages/web/application.py", line 288, in process
    return p(lambda: process(processors))
  File "/usr/local/lib/python2.7/dist-packages/web/application.py", line 700, in processor
    return handler()
  File "/usr/local/lib/python2.7/dist-packages/web/application.py", line 288, in <lambda>
    return p(lambda: process(processors))
  File "/usr/local/lib/python2.7/dist-packages/web/application.py", line 297, in process
    raise self.internalerror()
  File "/usr/local/lib/python2.7/dist-packages/web/application.py", line 588, in internalerror
    return debugerror()
  File "/usr/local/lib/python2.7/dist-packages/web/debugerror.py", line 337, in debugerror
    return web._InternalError(djangoerror())
  File "/usr/local/lib/python2.7/dist-packages/web/debugerror.py", line 315, in djangoerror
    djangoerror_r = Template(djangoerror_t, filename=__file__, filter=websafe)
  File "/usr/local/lib/python2.7/dist-packages/web/template.py", line 943, in __init__
    code = self.compile_template(text, filename)
  File "/usr/local/lib/python2.7/dist-packages/web/template.py", line 1020, in compile_template
    compiled_code = compile(code, filename, "exec")
  File "/usr/local/lib/python2.7/dist-packages/web/debugerror.pyc", line 8
    def with (exception_type, exception_value, frames)
           ^
SyntaxError: invalid syntax

Traceback (most recent call last):
  File "/usr/local/lib/python2.7/dist-packages/web/application.py", line 329, in wsgi
    result = self.handle_with_processors()
  File "/usr/local/lib/python2.7/dist-packages/web/application.py", line 300, in handle_with_processors
    return process(self.processors)
  File "/usr/local/lib/python2.7/dist-packages/web/application.py", line 297, in process
    raise self.internalerror()
  File "/usr/local/lib/python2.7/dist-packages/web/application.py", line 588, in internalerror
    return debugerror()
  File "/usr/local/lib/python2.7/dist-packages/web/debugerror.py", line 337, in debugerror
    return web._InternalError(djangoerror())
  File "/usr/local/lib/python2.7/dist-packages/web/debugerror.py", line 315, in djangoerror
    djangoerror_r = Template(djangoerror_t, filename=__file__, filter=websafe)
  File "/usr/local/lib/python2.7/dist-packages/web/template.py", line 943, in __init__
    code = self.compile_template(text, filename)
  File "/usr/local/lib/python2.7/dist-packages/web/template.py", line 1020, in compile_template
    compiled_code = compile(code, filename, "exec")
  File "/usr/local/lib/python2.7/dist-packages/web/debugerror.pyc", line 8
    def with (exception_type, exception_value, frames)
           ^
SyntaxError: invalid syntax

Template traceback:
    File '/usr/local/lib/python2.7/dist-packages/web/debugerror.pyc', line 8
        None
[pid: 9971|app: 0|req: 3/3] 192.168.1.29 () {38 vars in 754 bytes} [Sun Jan 28 10:25:46 2024] GET / => generated 0 bytes in 33 msecs (HTTP/1.1 500) 0 headers in 0 bytes (0 switches on core 0)
Traceback (most recent call last):
  File "/usr/local/lib/python2.7/dist-packages/web/application.py", line 290, in process
    return self.handle()
  File "/usr/local/lib/python2.7/dist-packages/web/application.py", line 281, in handle
    return self._delegate(fn, self.fvars, args)
  File "/usr/local/lib/python2.7/dist-packages/web/application.py", line 531, in _delegate
    return handle_class(cls)
  File "/usr/local/lib/python2.7/dist-packages/web/application.py", line 509, in handle_class
    return tocall(*args)
TypeError: GET() takes exactly 2 arguments (1 given)

Traceback (most recent call last):
  File "/usr/local/lib/python2.7/dist-packages/web/application.py", line 288, in process
    return p(lambda: process(processors))
  File "/usr/local/lib/python2.7/dist-packages/web/application.py", line 700, in processor
    return handler()
  File "/usr/local/lib/python2.7/dist-packages/web/application.py", line 288, in <lambda>
    return p(lambda: process(processors))
  File "/usr/local/lib/python2.7/dist-packages/web/application.py", line 297, in process
    raise self.internalerror()
  File "/usr/local/lib/python2.7/dist-packages/web/application.py", line 588, in internalerror
    return debugerror()
  File "/usr/local/lib/python2.7/dist-packages/web/debugerror.py", line 337, in debugerror
    return web._InternalError(djangoerror())
  File "/usr/local/lib/python2.7/dist-packages/web/debugerror.py", line 315, in djangoerror
    djangoerror_r = Template(djangoerror_t, filename=__file__, filter=websafe)
  File "/usr/local/lib/python2.7/dist-packages/web/template.py", line 943, in __init__
    code = self.compile_template(text, filename)
  File "/usr/local/lib/python2.7/dist-packages/web/template.py", line 1020, in compile_template
    compiled_code = compile(code, filename, "exec")
  File "/usr/local/lib/python2.7/dist-packages/web/debugerror.pyc", line 8
    def with (exception_type, exception_value, frames)
           ^
SyntaxError: invalid syntax

Traceback (most recent call last):
  File "/usr/local/lib/python2.7/dist-packages/web/application.py", line 288, in process
    return p(lambda: process(processors))
  File "/usr/local/lib/python2.7/dist-packages/web/application.py", line 700, in processor
    return handler()
  File "/usr/local/lib/python2.7/dist-packages/web/application.py", line 288, in <lambda>
    return p(lambda: process(processors))
  File "/usr/local/lib/python2.7/dist-packages/web/application.py", line 297, in process
    raise self.internalerror()
  File "/usr/local/lib/python2.7/dist-packages/web/application.py", line 588, in internalerror
    return debugerror()
  File "/usr/local/lib/python2.7/dist-packages/web/debugerror.py", line 337, in debugerror
    return web._InternalError(djangoerror())
  File "/usr/local/lib/python2.7/dist-packages/web/debugerror.py", line 315, in djangoerror
    djangoerror_r = Template(djangoerror_t, filename=__file__, filter=websafe)
  File "/usr/local/lib/python2.7/dist-packages/web/template.py", line 943, in __init__
    code = self.compile_template(text, filename)
  File "/usr/local/lib/python2.7/dist-packages/web/template.py", line 1020, in compile_template
    compiled_code = compile(code, filename, "exec")
  File "/usr/local/lib/python2.7/dist-packages/web/debugerror.pyc", line 8
    def with (exception_type, exception_value, frames)
           ^
SyntaxError: invalid syntax

Traceback (most recent call last):
  File "/usr/local/lib/python2.7/dist-packages/web/application.py", line 288, in process
    return p(lambda: process(processors))
  File "/usr/local/lib/python2.7/dist-packages/web/application.py", line 717, in processor
    result = handler()
  File "/usr/local/lib/python2.7/dist-packages/web/application.py", line 288, in <lambda>
    return p(lambda: process(processors))
  File "/usr/local/lib/python2.7/dist-packages/web/application.py", line 297, in process
    raise self.internalerror()
  File "/usr/local/lib/python2.7/dist-packages/web/application.py", line 588, in internalerror
    return debugerror()
  File "/usr/local/lib/python2.7/dist-packages/web/debugerror.py", line 337, in debugerror
    return web._InternalError(djangoerror())
  File "/usr/local/lib/python2.7/dist-packages/web/debugerror.py", line 315, in djangoerror
    djangoerror_r = Template(djangoerror_t, filename=__file__, filter=websafe)
  File "/usr/local/lib/python2.7/dist-packages/web/template.py", line 943, in __init__
    code = self.compile_template(text, filename)
  File "/usr/local/lib/python2.7/dist-packages/web/template.py", line 1020, in compile_template
    compiled_code = compile(code, filename, "exec")
  File "/usr/local/lib/python2.7/dist-packages/web/debugerror.pyc", line 8
    def with (exception_type, exception_value, frames)
           ^
SyntaxError: invalid syntax

Traceback (most recent call last):
  File "/usr/local/lib/python2.7/dist-packages/web/application.py", line 288, in process
    return p(lambda: process(processors))
  File "/usr/local/lib/python2.7/dist-packages/web/application.py", line 700, in processor
    return handler()
  File "/usr/local/lib/python2.7/dist-packages/web/application.py", line 288, in <lambda>
    return p(lambda: process(processors))
  File "/usr/local/lib/python2.7/dist-packages/web/application.py", line 297, in process
    raise self.internalerror()
  File "/usr/local/lib/python2.7/dist-packages/web/application.py", line 588, in internalerror
    return debugerror()
  File "/usr/local/lib/python2.7/dist-packages/web/debugerror.py", line 337, in debugerror
    return web._InternalError(djangoerror())
  File "/usr/local/lib/python2.7/dist-packages/web/debugerror.py", line 315, in djangoerror
    djangoerror_r = Template(djangoerror_t, filename=__file__, filter=websafe)
  File "/usr/local/lib/python2.7/dist-packages/web/template.py", line 943, in __init__
    code = self.compile_template(text, filename)
  File "/usr/local/lib/python2.7/dist-packages/web/template.py", line 1020, in compile_template
    compiled_code = compile(code, filename, "exec")
  File "/usr/local/lib/python2.7/dist-packages/web/debugerror.pyc", line 8
    def with (exception_type, exception_value, frames)
           ^
SyntaxError: invalid syntax

Traceback (most recent call last):
  File "/usr/local/lib/python2.7/dist-packages/web/application.py", line 329, in wsgi
    result = self.handle_with_processors()
  File "/usr/local/lib/python2.7/dist-packages/web/application.py", line 300, in handle_with_processors
    return process(self.processors)
  File "/usr/local/lib/python2.7/dist-packages/web/application.py", line 297, in process
    raise self.internalerror()
  File "/usr/local/lib/python2.7/dist-packages/web/application.py", line 588, in internalerror
    return debugerror()
  File "/usr/local/lib/python2.7/dist-packages/web/debugerror.py", line 337, in debugerror
    return web._InternalError(djangoerror())
  File "/usr/local/lib/python2.7/dist-packages/web/debugerror.py", line 315, in djangoerror
    djangoerror_r = Template(djangoerror_t, filename=__file__, filter=websafe)
  File "/usr/local/lib/python2.7/dist-packages/web/template.py", line 943, in __init__
    code = self.compile_template(text, filename)
  File "/usr/local/lib/python2.7/dist-packages/web/template.py", line 1020, in compile_template
    compiled_code = compile(code, filename, "exec")
  File "/usr/local/lib/python2.7/dist-packages/web/debugerror.pyc", line 8
    def with (exception_type, exception_value, frames)
           ^
SyntaxError: invalid syntax

Template traceback:
    File '/usr/local/lib/python2.7/dist-packages/web/debugerror.pyc', line 8
        None
[pid: 9971|app: 0|req: 4/4] 192.168.1.29 () {38 vars in 754 bytes} [Sun Jan 28 10:25:47 2024] GET / => generated 0 bytes in 50 msecs (HTTP/1.1 500) 0 headers in 0 bytes (0 switches on core 0)
Traceback (most recent call last):
  File "/usr/local/lib/python2.7/dist-packages/web/application.py", line 290, in process
    return self.handle()
  File "/usr/local/lib/python2.7/dist-packages/web/application.py", line 281, in handle
    return self._delegate(fn, self.fvars, args)
  File "/usr/local/lib/python2.7/dist-packages/web/application.py", line 531, in _delegate
    return handle_class(cls)
  File "/usr/local/lib/python2.7/dist-packages/web/application.py", line 509, in handle_class
    return tocall(*args)
TypeError: GET() takes exactly 2 arguments (1 given)

Traceback (most recent call last):
  File "/usr/local/lib/python2.7/dist-packages/web/application.py", line 288, in process
    return p(lambda: process(processors))
  File "/usr/local/lib/python2.7/dist-packages/web/application.py", line 700, in processor
    return handler()
  File "/usr/local/lib/python2.7/dist-packages/web/application.py", line 288, in <lambda>
    return p(lambda: process(processors))
  File "/usr/local/lib/python2.7/dist-packages/web/application.py", line 297, in process
    raise self.internalerror()
  File "/usr/local/lib/python2.7/dist-packages/web/application.py", line 588, in internalerror
    return debugerror()
  File "/usr/local/lib/python2.7/dist-packages/web/debugerror.py", line 337, in debugerror
    return web._InternalError(djangoerror())
  File "/usr/local/lib/python2.7/dist-packages/web/debugerror.py", line 315, in djangoerror
    djangoerror_r = Template(djangoerror_t, filename=__file__, filter=websafe)
  File "/usr/local/lib/python2.7/dist-packages/web/template.py", line 943, in __init__
    code = self.compile_template(text, filename)
  File "/usr/local/lib/python2.7/dist-packages/web/template.py", line 1020, in compile_template
    compiled_code = compile(code, filename, "exec")
  File "/usr/local/lib/python2.7/dist-packages/web/debugerror.pyc", line 8
    def with (exception_type, exception_value, frames)
           ^
SyntaxError: invalid syntax

Traceback (most recent call last):
  File "/usr/local/lib/python2.7/dist-packages/web/application.py", line 288, in process
    return p(lambda: process(processors))
  File "/usr/local/lib/python2.7/dist-packages/web/application.py", line 700, in processor
    return handler()
  File "/usr/local/lib/python2.7/dist-packages/web/application.py", line 288, in <lambda>
    return p(lambda: process(processors))
  File "/usr/local/lib/python2.7/dist-packages/web/application.py", line 297, in process
    raise self.internalerror()
  File "/usr/local/lib/python2.7/dist-packages/web/application.py", line 588, in internalerror
    return debugerror()
  File "/usr/local/lib/python2.7/dist-packages/web/debugerror.py", line 337, in debugerror
    return web._InternalError(djangoerror())
  File "/usr/local/lib/python2.7/dist-packages/web/debugerror.py", line 315, in djangoerror
    djangoerror_r = Template(djangoerror_t, filename=__file__, filter=websafe)
  File "/usr/local/lib/python2.7/dist-packages/web/template.py", line 943, in __init__
    code = self.compile_template(text, filename)
  File "/usr/local/lib/python2.7/dist-packages/web/template.py", line 1020, in compile_template
    compiled_code = compile(code, filename, "exec")
  File "/usr/local/lib/python2.7/dist-packages/web/debugerror.pyc", line 8
    def with (exception_type, exception_value, frames)
           ^
SyntaxError: invalid syntax

Traceback (most recent call last):
  File "/usr/local/lib/python2.7/dist-packages/web/application.py", line 288, in process
    return p(lambda: process(processors))
  File "/usr/local/lib/python2.7/dist-packages/web/application.py", line 717, in processor
    result = handler()
  File "/usr/local/lib/python2.7/dist-packages/web/application.py", line 288, in <lambda>
    return p(lambda: process(processors))
  File "/usr/local/lib/python2.7/dist-packages/web/application.py", line 297, in process
    raise self.internalerror()
  File "/usr/local/lib/python2.7/dist-packages/web/application.py", line 588, in internalerror
    return debugerror()
  File "/usr/local/lib/python2.7/dist-packages/web/debugerror.py", line 337, in debugerror
    return web._InternalError(djangoerror())
  File "/usr/local/lib/python2.7/dist-packages/web/debugerror.py", line 315, in djangoerror
    djangoerror_r = Template(djangoerror_t, filename=__file__, filter=websafe)
  File "/usr/local/lib/python2.7/dist-packages/web/template.py", line 943, in __init__
    code = self.compile_template(text, filename)
  File "/usr/local/lib/python2.7/dist-packages/web/template.py", line 1020, in compile_template
    compiled_code = compile(code, filename, "exec")
  File "/usr/local/lib/python2.7/dist-packages/web/debugerror.pyc", line 8
    def with (exception_type, exception_value, frames)
           ^
SyntaxError: invalid syntax

Traceback (most recent call last):
  File "/usr/local/lib/python2.7/dist-packages/web/application.py", line 288, in process
    return p(lambda: process(processors))
  File "/usr/local/lib/python2.7/dist-packages/web/application.py", line 700, in processor
    return handler()
  File "/usr/local/lib/python2.7/dist-packages/web/application.py", line 288, in <lambda>
    return p(lambda: process(processors))
  File "/usr/local/lib/python2.7/dist-packages/web/application.py", line 297, in process
    raise self.internalerror()
  File "/usr/local/lib/python2.7/dist-packages/web/application.py", line 588, in internalerror
    return debugerror()
  File "/usr/local/lib/python2.7/dist-packages/web/debugerror.py", line 337, in debugerror
    return web._InternalError(djangoerror())
  File "/usr/local/lib/python2.7/dist-packages/web/debugerror.py", line 315, in djangoerror
    djangoerror_r = Template(djangoerror_t, filename=__file__, filter=websafe)
  File "/usr/local/lib/python2.7/dist-packages/web/template.py", line 943, in __init__
    code = self.compile_template(text, filename)
  File "/usr/local/lib/python2.7/dist-packages/web/template.py", line 1020, in compile_template
    compiled_code = compile(code, filename, "exec")
  File "/usr/local/lib/python2.7/dist-packages/web/debugerror.pyc", line 8
    def with (exception_type, exception_value, frames)
           ^
SyntaxError: invalid syntax

Traceback (most recent call last):
  File "/usr/local/lib/python2.7/dist-packages/web/application.py", line 329, in wsgi
    result = self.handle_with_processors()
  File "/usr/local/lib/python2.7/dist-packages/web/application.py", line 300, in handle_with_processors
    return process(self.processors)
  File "/usr/local/lib/python2.7/dist-packages/web/application.py", line 297, in process
    raise self.internalerror()
  File "/usr/local/lib/python2.7/dist-packages/web/application.py", line 588, in internalerror
    return debugerror()
  File "/usr/local/lib/python2.7/dist-packages/web/debugerror.py", line 337, in debugerror
    return web._InternalError(djangoerror())
  File "/usr/local/lib/python2.7/dist-packages/web/debugerror.py", line 315, in djangoerror
    djangoerror_r = Template(djangoerror_t, filename=__file__, filter=websafe)
  File "/usr/local/lib/python2.7/dist-packages/web/template.py", line 943, in __init__
    code = self.compile_template(text, filename)
  File "/usr/local/lib/python2.7/dist-packages/web/template.py", line 1020, in compile_template
    compiled_code = compile(code, filename, "exec")
  File "/usr/local/lib/python2.7/dist-packages/web/debugerror.pyc", line 8
    def with (exception_type, exception_value, frames)
           ^
SyntaxError: invalid syntax

Template traceback:
    File '/usr/local/lib/python2.7/dist-packages/web/debugerror.pyc', line 8
        None
[pid: 9971|app: 0|req: 5/5] 192.168.1.29 () {38 vars in 754 bytes} [Sun Jan 28 10:25:47 2024] GET / => generated 0 bytes in 43 msecs (HTTP/1.1 500) 0 headers in 0 bytes (0 switches on core 0)
Traceback (most recent call last):
  File "/usr/local/lib/python2.7/dist-packages/web/application.py", line 290, in process
    return self.handle()
  File "/usr/local/lib/python2.7/dist-packages/web/application.py", line 281, in handle
    return self._delegate(fn, self.fvars, args)
  File "/usr/local/lib/python2.7/dist-packages/web/application.py", line 531, in _delegate
    return handle_class(cls)
  File "/usr/local/lib/python2.7/dist-packages/web/application.py", line 509, in handle_class
    return tocall(*args)
TypeError: GET() takes exactly 2 arguments (1 given)

Traceback (most recent call last):
  File "/usr/local/lib/python2.7/dist-packages/web/application.py", line 288, in process
    return p(lambda: process(processors))
  File "/usr/local/lib/python2.7/dist-packages/web/application.py", line 700, in processor
    return handler()
  File "/usr/local/lib/python2.7/dist-packages/web/application.py", line 288, in <lambda>
    return p(lambda: process(processors))
  File "/usr/local/lib/python2.7/dist-packages/web/application.py", line 297, in process
    raise self.internalerror()
  File "/usr/local/lib/python2.7/dist-packages/web/application.py", line 588, in internalerror
    return debugerror()
  File "/usr/local/lib/python2.7/dist-packages/web/debugerror.py", line 337, in debugerror
    return web._InternalError(djangoerror())
  File "/usr/local/lib/python2.7/dist-packages/web/debugerror.py", line 315, in djangoerror
    djangoerror_r = Template(djangoerror_t, filename=__file__, filter=websafe)
  File "/usr/local/lib/python2.7/dist-packages/web/template.py", line 943, in __init__
    code = self.compile_template(text, filename)
  File "/usr/local/lib/python2.7/dist-packages/web/template.py", line 1020, in compile_template
    compiled_code = compile(code, filename, "exec")
  File "/usr/local/lib/python2.7/dist-packages/web/debugerror.pyc", line 8
    def with (exception_type, exception_value, frames)
           ^
SyntaxError: invalid syntax

Traceback (most recent call last):
  File "/usr/local/lib/python2.7/dist-packages/web/application.py", line 288, in process
    return p(lambda: process(processors))
  File "/usr/local/lib/python2.7/dist-packages/web/application.py", line 700, in processor
    return handler()
  File "/usr/local/lib/python2.7/dist-packages/web/application.py", line 288, in <lambda>
    return p(lambda: process(processors))
  File "/usr/local/lib/python2.7/dist-packages/web/application.py", line 297, in process
    raise self.internalerror()
  File "/usr/local/lib/python2.7/dist-packages/web/application.py", line 588, in internalerror
    return debugerror()
  File "/usr/local/lib/python2.7/dist-packages/web/debugerror.py", line 337, in debugerror
    return web._InternalError(djangoerror())
  File "/usr/local/lib/python2.7/dist-packages/web/debugerror.py", line 315, in djangoerror
    djangoerror_r = Template(djangoerror_t, filename=__file__, filter=websafe)
  File "/usr/local/lib/python2.7/dist-packages/web/template.py", line 943, in __init__
    code = self.compile_template(text, filename)
  File "/usr/local/lib/python2.7/dist-packages/web/template.py", line 1020, in compile_template
    compiled_code = compile(code, filename, "exec")
  File "/usr/local/lib/python2.7/dist-packages/web/debugerror.pyc", line 8
    def with (exception_type, exception_value, frames)
           ^
SyntaxError: invalid syntax

Traceback (most recent call last):
  File "/usr/local/lib/python2.7/dist-packages/web/application.py", line 288, in process
    return p(lambda: process(processors))
  File "/usr/local/lib/python2.7/dist-packages/web/application.py", line 717, in processor
    result = handler()
  File "/usr/local/lib/python2.7/dist-packages/web/application.py", line 288, in <lambda>
    return p(lambda: process(processors))
  File "/usr/local/lib/python2.7/dist-packages/web/application.py", line 297, in process
    raise self.internalerror()
  File "/usr/local/lib/python2.7/dist-packages/web/application.py", line 588, in internalerror
    return debugerror()
  File "/usr/local/lib/python2.7/dist-packages/web/debugerror.py", line 337, in debugerror
    return web._InternalError(djangoerror())
  File "/usr/local/lib/python2.7/dist-packages/web/debugerror.py", line 315, in djangoerror
    djangoerror_r = Template(djangoerror_t, filename=__file__, filter=websafe)
  File "/usr/local/lib/python2.7/dist-packages/web/template.py", line 943, in __init__
    code = self.compile_template(text, filename)
  File "/usr/local/lib/python2.7/dist-packages/web/template.py", line 1020, in compile_template
    compiled_code = compile(code, filename, "exec")
  File "/usr/local/lib/python2.7/dist-packages/web/debugerror.pyc", line 8
    def with (exception_type, exception_value, frames)
           ^
SyntaxError: invalid syntax

Traceback (most recent call last):
  File "/usr/local/lib/python2.7/dist-packages/web/application.py", line 288, in process
    return p(lambda: process(processors))
  File "/usr/local/lib/python2.7/dist-packages/web/application.py", line 700, in processor
    return handler()
  File "/usr/local/lib/python2.7/dist-packages/web/application.py", line 288, in <lambda>
    return p(lambda: process(processors))
  File "/usr/local/lib/python2.7/dist-packages/web/application.py", line 297, in process
    raise self.internalerror()
  File "/usr/local/lib/python2.7/dist-packages/web/application.py", line 588, in internalerror
    return debugerror()
  File "/usr/local/lib/python2.7/dist-packages/web/debugerror.py", line 337, in debugerror
    return web._InternalError(djangoerror())
  File "/usr/local/lib/python2.7/dist-packages/web/debugerror.py", line 315, in djangoerror
    djangoerror_r = Template(djangoerror_t, filename=__file__, filter=websafe)
  File "/usr/local/lib/python2.7/dist-packages/web/template.py", line 943, in __init__
    code = self.compile_template(text, filename)
  File "/usr/local/lib/python2.7/dist-packages/web/template.py", line 1020, in compile_template
    compiled_code = compile(code, filename, "exec")
  File "/usr/local/lib/python2.7/dist-packages/web/debugerror.pyc", line 8
    def with (exception_type, exception_value, frames)
           ^
SyntaxError: invalid syntax

Traceback (most recent call last):
  File "/usr/local/lib/python2.7/dist-packages/web/application.py", line 329, in wsgi
    result = self.handle_with_processors()
  File "/usr/local/lib/python2.7/dist-packages/web/application.py", line 300, in handle_with_processors
    return process(self.processors)
  File "/usr/local/lib/python2.7/dist-packages/web/application.py", line 297, in process
    raise self.internalerror()
  File "/usr/local/lib/python2.7/dist-packages/web/application.py", line 588, in internalerror
    return debugerror()
  File "/usr/local/lib/python2.7/dist-packages/web/debugerror.py", line 337, in debugerror
    return web._InternalError(djangoerror())
  File "/usr/local/lib/python2.7/dist-packages/web/debugerror.py", line 315, in djangoerror
    djangoerror_r = Template(djangoerror_t, filename=__file__, filter=websafe)
  File "/usr/local/lib/python2.7/dist-packages/web/template.py", line 943, in __init__
    code = self.compile_template(text, filename)
  File "/usr/local/lib/python2.7/dist-packages/web/template.py", line 1020, in compile_template
    compiled_code = compile(code, filename, "exec")
  File "/usr/local/lib/python2.7/dist-packages/web/debugerror.pyc", line 8
    def with (exception_type, exception_value, frames)
           ^
SyntaxError: invalid syntax

Template traceback:
    File '/usr/local/lib/python2.7/dist-packages/web/debugerror.pyc', line 8
        None
[pid: 9971|app: 0|req: 6/6] 192.168.1.29 () {38 vars in 754 bytes} [Sun Jan 28 10:25:47 2024] GET / => generated 0 bytes in 31 msecs (HTTP/1.1 500) 0 headers in 0 bytes (0 switches on core 0)
Traceback (most recent call last):
  File "/usr/local/lib/python2.7/dist-packages/web/application.py", line 290, in process
    return self.handle()
  File "/usr/local/lib/python2.7/dist-packages/web/application.py", line 281, in handle
    return self._delegate(fn, self.fvars, args)
  File "/usr/local/lib/python2.7/dist-packages/web/application.py", line 531, in _delegate
    return handle_class(cls)
  File "/usr/local/lib/python2.7/dist-packages/web/application.py", line 509, in handle_class
    return tocall(*args)
TypeError: GET() takes exactly 2 arguments (1 given)

Traceback (most recent call last):
  File "/usr/local/lib/python2.7/dist-packages/web/application.py", line 288, in process
    return p(lambda: process(processors))
  File "/usr/local/lib/python2.7/dist-packages/web/application.py", line 700, in processor
    return handler()
  File "/usr/local/lib/python2.7/dist-packages/web/application.py", line 288, in <lambda>
    return p(lambda: process(processors))
  File "/usr/local/lib/python2.7/dist-packages/web/application.py", line 297, in process
    raise self.internalerror()
  File "/usr/local/lib/python2.7/dist-packages/web/application.py", line 588, in internalerror
    return debugerror()
  File "/usr/local/lib/python2.7/dist-packages/web/debugerror.py", line 337, in debugerror
    return web._InternalError(djangoerror())
  File "/usr/local/lib/python2.7/dist-packages/web/debugerror.py", line 315, in djangoerror
    djangoerror_r = Template(djangoerror_t, filename=__file__, filter=websafe)
  File "/usr/local/lib/python2.7/dist-packages/web/template.py", line 943, in __init__
    code = self.compile_template(text, filename)
  File "/usr/local/lib/python2.7/dist-packages/web/template.py", line 1020, in compile_template
    compiled_code = compile(code, filename, "exec")
  File "/usr/local/lib/python2.7/dist-packages/web/debugerror.pyc", line 8
    def with (exception_type, exception_value, frames)
           ^
SyntaxError: invalid syntax

Traceback (most recent call last):
  File "/usr/local/lib/python2.7/dist-packages/web/application.py", line 288, in process
    return p(lambda: process(processors))
  File "/usr/local/lib/python2.7/dist-packages/web/application.py", line 700, in processor
    return handler()
  File "/usr/local/lib/python2.7/dist-packages/web/application.py", line 288, in <lambda>
    return p(lambda: process(processors))
  File "/usr/local/lib/python2.7/dist-packages/web/application.py", line 297, in process
    raise self.internalerror()
  File "/usr/local/lib/python2.7/dist-packages/web/application.py", line 588, in internalerror
    return debugerror()
  File "/usr/local/lib/python2.7/dist-packages/web/debugerror.py", line 337, in debugerror
    return web._InternalError(djangoerror())
  File "/usr/local/lib/python2.7/dist-packages/web/debugerror.py", line 315, in djangoerror
    djangoerror_r = Template(djangoerror_t, filename=__file__, filter=websafe)
  File "/usr/local/lib/python2.7/dist-packages/web/template.py", line 943, in __init__
    code = self.compile_template(text, filename)
  File "/usr/local/lib/python2.7/dist-packages/web/template.py", line 1020, in compile_template
    compiled_code = compile(code, filename, "exec")
  File "/usr/local/lib/python2.7/dist-packages/web/debugerror.pyc", line 8
    def with (exception_type, exception_value, frames)
           ^
SyntaxError: invalid syntax

Traceback (most recent call last):
  File "/usr/local/lib/python2.7/dist-packages/web/application.py", line 288, in process
    return p(lambda: process(processors))
  File "/usr/local/lib/python2.7/dist-packages/web/application.py", line 717, in processor
    result = handler()
  File "/usr/local/lib/python2.7/dist-packages/web/application.py", line 288, in <lambda>
    return p(lambda: process(processors))
  File "/usr/local/lib/python2.7/dist-packages/web/application.py", line 297, in process
    raise self.internalerror()
  File "/usr/local/lib/python2.7/dist-packages/web/application.py", line 588, in internalerror
    return debugerror()
  File "/usr/local/lib/python2.7/dist-packages/web/debugerror.py", line 337, in debugerror
    return web._InternalError(djangoerror())
  File "/usr/local/lib/python2.7/dist-packages/web/debugerror.py", line 315, in djangoerror
    djangoerror_r = Template(djangoerror_t, filename=__file__, filter=websafe)
  File "/usr/local/lib/python2.7/dist-packages/web/template.py", line 943, in __init__
    code = self.compile_template(text, filename)
  File "/usr/local/lib/python2.7/dist-packages/web/template.py", line 1020, in compile_template
    compiled_code = compile(code, filename, "exec")
  File "/usr/local/lib/python2.7/dist-packages/web/debugerror.pyc", line 8
    def with (exception_type, exception_value, frames)
           ^
SyntaxError: invalid syntax

Traceback (most recent call last):
  File "/usr/local/lib/python2.7/dist-packages/web/application.py", line 288, in process
    return p(lambda: process(processors))
  File "/usr/local/lib/python2.7/dist-packages/web/application.py", line 700, in processor
    return handler()
  File "/usr/local/lib/python2.7/dist-packages/web/application.py", line 288, in <lambda>
    return p(lambda: process(processors))
  File "/usr/local/lib/python2.7/dist-packages/web/application.py", line 297, in process
    raise self.internalerror()
  File "/usr/local/lib/python2.7/dist-packages/web/application.py", line 588, in internalerror
    return debugerror()
  File "/usr/local/lib/python2.7/dist-packages/web/debugerror.py", line 337, in debugerror
    return web._InternalError(djangoerror())
  File "/usr/local/lib/python2.7/dist-packages/web/debugerror.py", line 315, in djangoerror
    djangoerror_r = Template(djangoerror_t, filename=__file__, filter=websafe)
  File "/usr/local/lib/python2.7/dist-packages/web/template.py", line 943, in __init__
    code = self.compile_template(text, filename)
  File "/usr/local/lib/python2.7/dist-packages/web/template.py", line 1020, in compile_template
    compiled_code = compile(code, filename, "exec")
  File "/usr/local/lib/python2.7/dist-packages/web/debugerror.pyc", line 8
    def with (exception_type, exception_value, frames)
           ^
SyntaxError: invalid syntax

Traceback (most recent call last):
  File "/usr/local/lib/python2.7/dist-packages/web/application.py", line 329, in wsgi
    result = self.handle_with_processors()
  File "/usr/local/lib/python2.7/dist-packages/web/application.py", line 300, in handle_with_processors
    return process(self.processors)
  File "/usr/local/lib/python2.7/dist-packages/web/application.py", line 297, in process
    raise self.internalerror()
  File "/usr/local/lib/python2.7/dist-packages/web/application.py", line 588, in internalerror
    return debugerror()
  File "/usr/local/lib/python2.7/dist-packages/web/debugerror.py", line 337, in debugerror
    return web._InternalError(djangoerror())
  File "/usr/local/lib/python2.7/dist-packages/web/debugerror.py", line 315, in djangoerror
    djangoerror_r = Template(djangoerror_t, filename=__file__, filter=websafe)
  File "/usr/local/lib/python2.7/dist-packages/web/template.py", line 943, in __init__
    code = self.compile_template(text, filename)
  File "/usr/local/lib/python2.7/dist-packages/web/template.py", line 1020, in compile_template
    compiled_code = compile(code, filename, "exec")
  File "/usr/local/lib/python2.7/dist-packages/web/debugerror.pyc", line 8
    def with (exception_type, exception_value, frames)
           ^
SyntaxError: invalid syntax

Template traceback:
    File '/usr/local/lib/python2.7/dist-packages/web/debugerror.pyc', line 8
        None
[pid: 9971|app: 0|req: 7/7] 192.168.1.29 () {38 vars in 754 bytes} [Sun Jan 28 10:25:52 2024] GET / => generated 0 bytes in 42 msecs (HTTP/1.1 500) 0 headers in 0 bytes (0 switches on core 0)
Traceback (most recent call last):
  File "/usr/local/lib/python2.7/dist-packages/web/application.py", line 290, in process
    return self.handle()
  File "/usr/local/lib/python2.7/dist-packages/web/application.py", line 281, in handle
    return self._delegate(fn, self.fvars, args)
  File "/usr/local/lib/python2.7/dist-packages/web/application.py", line 531, in _delegate
    return handle_class(cls)
  File "/usr/local/lib/python2.7/dist-packages/web/application.py", line 509, in handle_class
    return tocall(*args)
TypeError: GET() takes exactly 2 arguments (1 given)

Traceback (most recent call last):
  File "/usr/local/lib/python2.7/dist-packages/web/application.py", line 288, in process
    return p(lambda: process(processors))
  File "/usr/local/lib/python2.7/dist-packages/web/application.py", line 700, in processor
    return handler()
  File "/usr/local/lib/python2.7/dist-packages/web/application.py", line 288, in <lambda>
    return p(lambda: process(processors))
  File "/usr/local/lib/python2.7/dist-packages/web/application.py", line 297, in process
    raise self.internalerror()
  File "/usr/local/lib/python2.7/dist-packages/web/application.py", line 588, in internalerror
    return debugerror()
  File "/usr/local/lib/python2.7/dist-packages/web/debugerror.py", line 337, in debugerror
    return web._InternalError(djangoerror())
  File "/usr/local/lib/python2.7/dist-packages/web/debugerror.py", line 315, in djangoerror
    djangoerror_r = Template(djangoerror_t, filename=__file__, filter=websafe)
  File "/usr/local/lib/python2.7/dist-packages/web/template.py", line 943, in __init__
    code = self.compile_template(text, filename)
  File "/usr/local/lib/python2.7/dist-packages/web/template.py", line 1020, in compile_template
    compiled_code = compile(code, filename, "exec")
  File "/usr/local/lib/python2.7/dist-packages/web/debugerror.pyc", line 8
    def with (exception_type, exception_value, frames)
           ^
SyntaxError: invalid syntax

Traceback (most recent call last):
  File "/usr/local/lib/python2.7/dist-packages/web/application.py", line 288, in process
    return p(lambda: process(processors))
  File "/usr/local/lib/python2.7/dist-packages/web/application.py", line 700, in processor
    return handler()
  File "/usr/local/lib/python2.7/dist-packages/web/application.py", line 288, in <lambda>
    return p(lambda: process(processors))
  File "/usr/local/lib/python2.7/dist-packages/web/application.py", line 297, in process
    raise self.internalerror()
  File "/usr/local/lib/python2.7/dist-packages/web/application.py", line 588, in internalerror
    return debugerror()
  File "/usr/local/lib/python2.7/dist-packages/web/debugerror.py", line 337, in debugerror
    return web._InternalError(djangoerror())
  File "/usr/local/lib/python2.7/dist-packages/web/debugerror.py", line 315, in djangoerror
    djangoerror_r = Template(djangoerror_t, filename=__file__, filter=websafe)
  File "/usr/local/lib/python2.7/dist-packages/web/template.py", line 943, in __init__
    code = self.compile_template(text, filename)
  File "/usr/local/lib/python2.7/dist-packages/web/template.py", line 1020, in compile_template
    compiled_code = compile(code, filename, "exec")
  File "/usr/local/lib/python2.7/dist-packages/web/debugerror.pyc", line 8
    def with (exception_type, exception_value, frames)
           ^
SyntaxError: invalid syntax

Traceback (most recent call last):
  File "/usr/local/lib/python2.7/dist-packages/web/application.py", line 288, in process
    return p(lambda: process(processors))
  File "/usr/local/lib/python2.7/dist-packages/web/application.py", line 717, in processor
    result = handler()
  File "/usr/local/lib/python2.7/dist-packages/web/application.py", line 288, in <lambda>
    return p(lambda: process(processors))
  File "/usr/local/lib/python2.7/dist-packages/web/application.py", line 297, in process
    raise self.internalerror()
  File "/usr/local/lib/python2.7/dist-packages/web/application.py", line 588, in internalerror
    return debugerror()
  File "/usr/local/lib/python2.7/dist-packages/web/debugerror.py", line 337, in debugerror
    return web._InternalError(djangoerror())
  File "/usr/local/lib/python2.7/dist-packages/web/debugerror.py", line 315, in djangoerror
    djangoerror_r = Template(djangoerror_t, filename=__file__, filter=websafe)
  File "/usr/local/lib/python2.7/dist-packages/web/template.py", line 943, in __init__
    code = self.compile_template(text, filename)
  File "/usr/local/lib/python2.7/dist-packages/web/template.py", line 1020, in compile_template
    compiled_code = compile(code, filename, "exec")
  File "/usr/local/lib/python2.7/dist-packages/web/debugerror.pyc", line 8
    def with (exception_type, exception_value, frames)
           ^
SyntaxError: invalid syntax

Traceback (most recent call last):
  File "/usr/local/lib/python2.7/dist-packages/web/application.py", line 288, in process
    return p(lambda: process(processors))
  File "/usr/local/lib/python2.7/dist-packages/web/application.py", line 700, in processor
    return handler()
  File "/usr/local/lib/python2.7/dist-packages/web/application.py", line 288, in <lambda>
    return p(lambda: process(processors))
  File "/usr/local/lib/python2.7/dist-packages/web/application.py", line 297, in process
    raise self.internalerror()
  File "/usr/local/lib/python2.7/dist-packages/web/application.py", line 588, in internalerror
    return debugerror()
  File "/usr/local/lib/python2.7/dist-packages/web/debugerror.py", line 337, in debugerror
    return web._InternalError(djangoerror())
  File "/usr/local/lib/python2.7/dist-packages/web/debugerror.py", line 315, in djangoerror
    djangoerror_r = Template(djangoerror_t, filename=__file__, filter=websafe)
  File "/usr/local/lib/python2.7/dist-packages/web/template.py", line 943, in __init__
    code = self.compile_template(text, filename)
  File "/usr/local/lib/python2.7/dist-packages/web/template.py", line 1020, in compile_template
    compiled_code = compile(code, filename, "exec")
  File "/usr/local/lib/python2.7/dist-packages/web/debugerror.pyc", line 8
    def with (exception_type, exception_value, frames)
           ^
SyntaxError: invalid syntax

Traceback (most recent call last):
  File "/usr/local/lib/python2.7/dist-packages/web/application.py", line 329, in wsgi
    result = self.handle_with_processors()
  File "/usr/local/lib/python2.7/dist-packages/web/application.py", line 300, in handle_with_processors
    return process(self.processors)
  File "/usr/local/lib/python2.7/dist-packages/web/application.py", line 297, in process
    raise self.internalerror()
  File "/usr/local/lib/python2.7/dist-packages/web/application.py", line 588, in internalerror
    return debugerror()
  File "/usr/local/lib/python2.7/dist-packages/web/debugerror.py", line 337, in debugerror
    return web._InternalError(djangoerror())
  File "/usr/local/lib/python2.7/dist-packages/web/debugerror.py", line 315, in djangoerror
    djangoerror_r = Template(djangoerror_t, filename=__file__, filter=websafe)
  File "/usr/local/lib/python2.7/dist-packages/web/template.py", line 943, in __init__
    code = self.compile_template(text, filename)
  File "/usr/local/lib/python2.7/dist-packages/web/template.py", line 1020, in compile_template
    compiled_code = compile(code, filename, "exec")
  File "/usr/local/lib/python2.7/dist-packages/web/debugerror.pyc", line 8
    def with (exception_type, exception_value, frames)
           ^
SyntaxError: invalid syntax

Template traceback:
    File '/usr/local/lib/python2.7/dist-packages/web/debugerror.pyc', line 8
        None
[pid: 9971|app: 0|req: 8/8] 192.168.1.29 () {38 vars in 754 bytes} [Sun Jan 28 10:25:53 2024] GET / => generated 0 bytes in 37 msecs (HTTP/1.1 500) 0 headers in 0 bytes (0 switches on core 0)
Traceback (most recent call last):
  File "/usr/local/lib/python2.7/dist-packages/web/application.py", line 290, in process
    return self.handle()
  File "/usr/local/lib/python2.7/dist-packages/web/application.py", line 281, in handle
    return self._delegate(fn, self.fvars, args)
  File "/usr/local/lib/python2.7/dist-packages/web/application.py", line 531, in _delegate
    return handle_class(cls)
  File "/usr/local/lib/python2.7/dist-packages/web/application.py", line 509, in handle_class
    return tocall(*args)
TypeError: GET() takes exactly 2 arguments (1 given)

Traceback (most recent call last):
  File "/usr/local/lib/python2.7/dist-packages/web/application.py", line 288, in process
    return p(lambda: process(processors))
  File "/usr/local/lib/python2.7/dist-packages/web/application.py", line 700, in processor
    return handler()
  File "/usr/local/lib/python2.7/dist-packages/web/application.py", line 288, in <lambda>
    return p(lambda: process(processors))
  File "/usr/local/lib/python2.7/dist-packages/web/application.py", line 297, in process
    raise self.internalerror()
  File "/usr/local/lib/python2.7/dist-packages/web/application.py", line 588, in internalerror
    return debugerror()
  File "/usr/local/lib/python2.7/dist-packages/web/debugerror.py", line 337, in debugerror
    return web._InternalError(djangoerror())
  File "/usr/local/lib/python2.7/dist-packages/web/debugerror.py", line 315, in djangoerror
    djangoerror_r = Template(djangoerror_t, filename=__file__, filter=websafe)
  File "/usr/local/lib/python2.7/dist-packages/web/template.py", line 943, in __init__
    code = self.compile_template(text, filename)
  File "/usr/local/lib/python2.7/dist-packages/web/template.py", line 1020, in compile_template
    compiled_code = compile(code, filename, "exec")
  File "/usr/local/lib/python2.7/dist-packages/web/debugerror.pyc", line 8
    def with (exception_type, exception_value, frames)
           ^
SyntaxError: invalid syntax

Traceback (most recent call last):
  File "/usr/local/lib/python2.7/dist-packages/web/application.py", line 288, in process
    return p(lambda: process(processors))
  File "/usr/local/lib/python2.7/dist-packages/web/application.py", line 700, in processor
    return handler()
  File "/usr/local/lib/python2.7/dist-packages/web/application.py", line 288, in <lambda>
    return p(lambda: process(processors))
  File "/usr/local/lib/python2.7/dist-packages/web/application.py", line 297, in process
    raise self.internalerror()
  File "/usr/local/lib/python2.7/dist-packages/web/application.py", line 588, in internalerror
    return debugerror()
  File "/usr/local/lib/python2.7/dist-packages/web/debugerror.py", line 337, in debugerror
    return web._InternalError(djangoerror())
  File "/usr/local/lib/python2.7/dist-packages/web/debugerror.py", line 315, in djangoerror
    djangoerror_r = Template(djangoerror_t, filename=__file__, filter=websafe)
  File "/usr/local/lib/python2.7/dist-packages/web/template.py", line 943, in __init__
    code = self.compile_template(text, filename)
  File "/usr/local/lib/python2.7/dist-packages/web/template.py", line 1020, in compile_template
    compiled_code = compile(code, filename, "exec")
  File "/usr/local/lib/python2.7/dist-packages/web/debugerror.pyc", line 8
    def with (exception_type, exception_value, frames)
           ^
SyntaxError: invalid syntax

Traceback (most recent call last):
  File "/usr/local/lib/python2.7/dist-packages/web/application.py", line 288, in process
    return p(lambda: process(processors))
  File "/usr/local/lib/python2.7/dist-packages/web/application.py", line 717, in processor
    result = handler()
  File "/usr/local/lib/python2.7/dist-packages/web/application.py", line 288, in <lambda>
    return p(lambda: process(processors))
  File "/usr/local/lib/python2.7/dist-packages/web/application.py", line 297, in process
    raise self.internalerror()
  File "/usr/local/lib/python2.7/dist-packages/web/application.py", line 588, in internalerror
    return debugerror()
  File "/usr/local/lib/python2.7/dist-packages/web/debugerror.py", line 337, in debugerror
    return web._InternalError(djangoerror())
  File "/usr/local/lib/python2.7/dist-packages/web/debugerror.py", line 315, in djangoerror
    djangoerror_r = Template(djangoerror_t, filename=__file__, filter=websafe)
  File "/usr/local/lib/python2.7/dist-packages/web/template.py", line 943, in __init__
    code = self.compile_template(text, filename)
  File "/usr/local/lib/python2.7/dist-packages/web/template.py", line 1020, in compile_template
    compiled_code = compile(code, filename, "exec")
  File "/usr/local/lib/python2.7/dist-packages/web/debugerror.pyc", line 8
    def with (exception_type, exception_value, frames)
           ^
SyntaxError: invalid syntax

Traceback (most recent call last):
  File "/usr/local/lib/python2.7/dist-packages/web/application.py", line 288, in process
    return p(lambda: process(processors))
  File "/usr/local/lib/python2.7/dist-packages/web/application.py", line 700, in processor
    return handler()
  File "/usr/local/lib/python2.7/dist-packages/web/application.py", line 288, in <lambda>
    return p(lambda: process(processors))
  File "/usr/local/lib/python2.7/dist-packages/web/application.py", line 297, in process
    raise self.internalerror()
  File "/usr/local/lib/python2.7/dist-packages/web/application.py", line 588, in internalerror
    return debugerror()
  File "/usr/local/lib/python2.7/dist-packages/web/debugerror.py", line 337, in debugerror
    return web._InternalError(djangoerror())
  File "/usr/local/lib/python2.7/dist-packages/web/debugerror.py", line 315, in djangoerror
    djangoerror_r = Template(djangoerror_t, filename=__file__, filter=websafe)
  File "/usr/local/lib/python2.7/dist-packages/web/template.py", line 943, in __init__
    code = self.compile_template(text, filename)
  File "/usr/local/lib/python2.7/dist-packages/web/template.py", line 1020, in compile_template
    compiled_code = compile(code, filename, "exec")
  File "/usr/local/lib/python2.7/dist-packages/web/debugerror.pyc", line 8
    def with (exception_type, exception_value, frames)
           ^
SyntaxError: invalid syntax

Traceback (most recent call last):
  File "/usr/local/lib/python2.7/dist-packages/web/application.py", line 329, in wsgi
    result = self.handle_with_processors()
  File "/usr/local/lib/python2.7/dist-packages/web/application.py", line 300, in handle_with_processors
    return process(self.processors)
  File "/usr/local/lib/python2.7/dist-packages/web/application.py", line 297, in process
    raise self.internalerror()
  File "/usr/local/lib/python2.7/dist-packages/web/application.py", line 588, in internalerror
    return debugerror()
  File "/usr/local/lib/python2.7/dist-packages/web/debugerror.py", line 337, in debugerror
    return web._InternalError(djangoerror())
  File "/usr/local/lib/python2.7/dist-packages/web/debugerror.py", line 315, in djangoerror
    djangoerror_r = Template(djangoerror_t, filename=__file__, filter=websafe)
  File "/usr/local/lib/python2.7/dist-packages/web/template.py", line 943, in __init__
    code = self.compile_template(text, filename)
  File "/usr/local/lib/python2.7/dist-packages/web/template.py", line 1020, in compile_template
    compiled_code = compile(code, filename, "exec")
  File "/usr/local/lib/python2.7/dist-packages/web/debugerror.pyc", line 8
    def with (exception_type, exception_value, frames)
           ^
SyntaxError: invalid syntax

Template traceback:
    File '/usr/local/lib/python2.7/dist-packages/web/debugerror.pyc', line 8
        None
[pid: 9971|app: 0|req: 9/9] 192.168.1.29 () {38 vars in 754 bytes} [Sun Jan 28 10:25:53 2024] GET / => generated 0 bytes in 29 msecs (HTTP/1.1 500) 0 headers in 0 bytes (0 switches on core 0)
Traceback (most recent call last):
  File "/usr/local/lib/python2.7/dist-packages/web/application.py", line 290, in process
    return self.handle()
  File "/usr/local/lib/python2.7/dist-packages/web/application.py", line 281, in handle
    return self._delegate(fn, self.fvars, args)
  File "/usr/local/lib/python2.7/dist-packages/web/application.py", line 531, in _delegate
    return handle_class(cls)
  File "/usr/local/lib/python2.7/dist-packages/web/application.py", line 509, in handle_class
    return tocall(*args)
TypeError: GET() takes exactly 2 arguments (1 given)

Traceback (most recent call last):
  File "/usr/local/lib/python2.7/dist-packages/web/application.py", line 288, in process
    return p(lambda: process(processors))
  File "/usr/local/lib/python2.7/dist-packages/web/application.py", line 700, in processor
    return handler()
  File "/usr/local/lib/python2.7/dist-packages/web/application.py", line 288, in <lambda>
    return p(lambda: process(processors))
  File "/usr/local/lib/python2.7/dist-packages/web/application.py", line 297, in process
    raise self.internalerror()
  File "/usr/local/lib/python2.7/dist-packages/web/application.py", line 588, in internalerror
    return debugerror()
  File "/usr/local/lib/python2.7/dist-packages/web/debugerror.py", line 337, in debugerror
    return web._InternalError(djangoerror())
  File "/usr/local/lib/python2.7/dist-packages/web/debugerror.py", line 315, in djangoerror
    djangoerror_r = Template(djangoerror_t, filename=__file__, filter=websafe)
  File "/usr/local/lib/python2.7/dist-packages/web/template.py", line 943, in __init__
    code = self.compile_template(text, filename)
  File "/usr/local/lib/python2.7/dist-packages/web/template.py", line 1020, in compile_template
    compiled_code = compile(code, filename, "exec")
  File "/usr/local/lib/python2.7/dist-packages/web/debugerror.pyc", line 8
    def with (exception_type, exception_value, frames)
           ^
SyntaxError: invalid syntax

Traceback (most recent call last):
  File "/usr/local/lib/python2.7/dist-packages/web/application.py", line 288, in process
    return p(lambda: process(processors))
  File "/usr/local/lib/python2.7/dist-packages/web/application.py", line 700, in processor
    return handler()
  File "/usr/local/lib/python2.7/dist-packages/web/application.py", line 288, in <lambda>
    return p(lambda: process(processors))
  File "/usr/local/lib/python2.7/dist-packages/web/application.py", line 297, in process
    raise self.internalerror()
  File "/usr/local/lib/python2.7/dist-packages/web/application.py", line 588, in internalerror
    return debugerror()
  File "/usr/local/lib/python2.7/dist-packages/web/debugerror.py", line 337, in debugerror
    return web._InternalError(djangoerror())
  File "/usr/local/lib/python2.7/dist-packages/web/debugerror.py", line 315, in djangoerror
    djangoerror_r = Template(djangoerror_t, filename=__file__, filter=websafe)
  File "/usr/local/lib/python2.7/dist-packages/web/template.py", line 943, in __init__
    code = self.compile_template(text, filename)
  File "/usr/local/lib/python2.7/dist-packages/web/template.py", line 1020, in compile_template
    compiled_code = compile(code, filename, "exec")
  File "/usr/local/lib/python2.7/dist-packages/web/debugerror.pyc", line 8
    def with (exception_type, exception_value, frames)
           ^
SyntaxError: invalid syntax

Traceback (most recent call last):
  File "/usr/local/lib/python2.7/dist-packages/web/application.py", line 288, in process
    return p(lambda: process(processors))
  File "/usr/local/lib/python2.7/dist-packages/web/application.py", line 717, in processor
    result = handler()
  File "/usr/local/lib/python2.7/dist-packages/web/application.py", line 288, in <lambda>
    return p(lambda: process(processors))
  File "/usr/local/lib/python2.7/dist-packages/web/application.py", line 297, in process
    raise self.internalerror()
  File "/usr/local/lib/python2.7/dist-packages/web/application.py", line 588, in internalerror
    return debugerror()
  File "/usr/local/lib/python2.7/dist-packages/web/debugerror.py", line 337, in debugerror
    return web._InternalError(djangoerror())
  File "/usr/local/lib/python2.7/dist-packages/web/debugerror.py", line 315, in djangoerror
    djangoerror_r = Template(djangoerror_t, filename=__file__, filter=websafe)
  File "/usr/local/lib/python2.7/dist-packages/web/template.py", line 943, in __init__
    code = self.compile_template(text, filename)
  File "/usr/local/lib/python2.7/dist-packages/web/template.py", line 1020, in compile_template
    compiled_code = compile(code, filename, "exec")
  File "/usr/local/lib/python2.7/dist-packages/web/debugerror.pyc", line 8
    def with (exception_type, exception_value, frames)
           ^
SyntaxError: invalid syntax

Traceback (most recent call last):
  File "/usr/local/lib/python2.7/dist-packages/web/application.py", line 288, in process
    return p(lambda: process(processors))
  File "/usr/local/lib/python2.7/dist-packages/web/application.py", line 700, in processor
    return handler()
  File "/usr/local/lib/python2.7/dist-packages/web/application.py", line 288, in <lambda>
    return p(lambda: process(processors))
  File "/usr/local/lib/python2.7/dist-packages/web/application.py", line 297, in process
    raise self.internalerror()
  File "/usr/local/lib/python2.7/dist-packages/web/application.py", line 588, in internalerror
    return debugerror()
  File "/usr/local/lib/python2.7/dist-packages/web/debugerror.py", line 337, in debugerror
    return web._InternalError(djangoerror())
  File "/usr/local/lib/python2.7/dist-packages/web/debugerror.py", line 315, in djangoerror
    djangoerror_r = Template(djangoerror_t, filename=__file__, filter=websafe)
  File "/usr/local/lib/python2.7/dist-packages/web/template.py", line 943, in __init__
    code = self.compile_template(text, filename)
  File "/usr/local/lib/python2.7/dist-packages/web/template.py", line 1020, in compile_template
    compiled_code = compile(code, filename, "exec")
  File "/usr/local/lib/python2.7/dist-packages/web/debugerror.pyc", line 8
    def with (exception_type, exception_value, frames)
           ^
SyntaxError: invalid syntax

Traceback (most recent call last):
  File "/usr/local/lib/python2.7/dist-packages/web/application.py", line 329, in wsgi
    result = self.handle_with_processors()
  File "/usr/local/lib/python2.7/dist-packages/web/application.py", line 300, in handle_with_processors
    return process(self.processors)
  File "/usr/local/lib/python2.7/dist-packages/web/application.py", line 297, in process
    raise self.internalerror()
  File "/usr/local/lib/python2.7/dist-packages/web/application.py", line 588, in internalerror
    return debugerror()
  File "/usr/local/lib/python2.7/dist-packages/web/debugerror.py", line 337, in debugerror
    return web._InternalError(djangoerror())
  File "/usr/local/lib/python2.7/dist-packages/web/debugerror.py", line 315, in djangoerror
    djangoerror_r = Template(djangoerror_t, filename=__file__, filter=websafe)
  File "/usr/local/lib/python2.7/dist-packages/web/template.py", line 943, in __init__
    code = self.compile_template(text, filename)
  File "/usr/local/lib/python2.7/dist-packages/web/template.py", line 1020, in compile_template
    compiled_code = compile(code, filename, "exec")
  File "/usr/local/lib/python2.7/dist-packages/web/debugerror.pyc", line 8
    def with (exception_type, exception_value, frames)
           ^
SyntaxError: invalid syntax

Template traceback:
    File '/usr/local/lib/python2.7/dist-packages/web/debugerror.pyc', line 8
        None
[pid: 9971|app: 0|req: 10/10] 192.168.1.29 () {38 vars in 754 bytes} [Sun Jan 28 10:26:23 2024] GET / => generated 0 bytes in 41 msecs (HTTP/1.1 500) 0 headers in 0 bytes (0 switches on core 0)
Traceback (most recent call last):
  File "/usr/local/lib/python2.7/dist-packages/web/application.py", line 290, in process
    return self.handle()
  File "/usr/local/lib/python2.7/dist-packages/web/application.py", line 281, in handle
    return self._delegate(fn, self.fvars, args)
  File "/usr/local/lib/python2.7/dist-packages/web/application.py", line 531, in _delegate
    return handle_class(cls)
  File "/usr/local/lib/python2.7/dist-packages/web/application.py", line 509, in handle_class
    return tocall(*args)
TypeError: GET() takes exactly 2 arguments (1 given)

Traceback (most recent call last):
  File "/usr/local/lib/python2.7/dist-packages/web/application.py", line 288, in process
    return p(lambda: process(processors))
  File "/usr/local/lib/python2.7/dist-packages/web/application.py", line 700, in processor
    return handler()
  File "/usr/local/lib/python2.7/dist-packages/web/application.py", line 288, in <lambda>
    return p(lambda: process(processors))
  File "/usr/local/lib/python2.7/dist-packages/web/application.py", line 297, in process
    raise self.internalerror()
  File "/usr/local/lib/python2.7/dist-packages/web/application.py", line 588, in internalerror
    return debugerror()
  File "/usr/local/lib/python2.7/dist-packages/web/debugerror.py", line 337, in debugerror
    return web._InternalError(djangoerror())
  File "/usr/local/lib/python2.7/dist-packages/web/debugerror.py", line 315, in djangoerror
    djangoerror_r = Template(djangoerror_t, filename=__file__, filter=websafe)
  File "/usr/local/lib/python2.7/dist-packages/web/template.py", line 943, in __init__
    code = self.compile_template(text, filename)
  File "/usr/local/lib/python2.7/dist-packages/web/template.py", line 1020, in compile_template
    compiled_code = compile(code, filename, "exec")
  File "/usr/local/lib/python2.7/dist-packages/web/debugerror.pyc", line 8
    def with (exception_type, exception_value, frames)
           ^
SyntaxError: invalid syntax

Traceback (most recent call last):
  File "/usr/local/lib/python2.7/dist-packages/web/application.py", line 288, in process
    return p(lambda: process(processors))
  File "/usr/local/lib/python2.7/dist-packages/web/application.py", line 700, in processor
    return handler()
  File "/usr/local/lib/python2.7/dist-packages/web/application.py", line 288, in <lambda>
    return p(lambda: process(processors))
  File "/usr/local/lib/python2.7/dist-packages/web/application.py", line 297, in process
    raise self.internalerror()
  File "/usr/local/lib/python2.7/dist-packages/web/application.py", line 588, in internalerror
    return debugerror()
  File "/usr/local/lib/python2.7/dist-packages/web/debugerror.py", line 337, in debugerror
    return web._InternalError(djangoerror())
  File "/usr/local/lib/python2.7/dist-packages/web/debugerror.py", line 315, in djangoerror
    djangoerror_r = Template(djangoerror_t, filename=__file__, filter=websafe)
  File "/usr/local/lib/python2.7/dist-packages/web/template.py", line 943, in __init__
    code = self.compile_template(text, filename)
  File "/usr/local/lib/python2.7/dist-packages/web/template.py", line 1020, in compile_template
    compiled_code = compile(code, filename, "exec")
  File "/usr/local/lib/python2.7/dist-packages/web/debugerror.pyc", line 8
    def with (exception_type, exception_value, frames)
           ^
SyntaxError: invalid syntax

Traceback (most recent call last):
  File "/usr/local/lib/python2.7/dist-packages/web/application.py", line 288, in process
    return p(lambda: process(processors))
  File "/usr/local/lib/python2.7/dist-packages/web/application.py", line 717, in processor
    result = handler()
  File "/usr/local/lib/python2.7/dist-packages/web/application.py", line 288, in <lambda>
    return p(lambda: process(processors))
  File "/usr/local/lib/python2.7/dist-packages/web/application.py", line 297, in process
    raise self.internalerror()
  File "/usr/local/lib/python2.7/dist-packages/web/application.py", line 588, in internalerror
    return debugerror()
  File "/usr/local/lib/python2.7/dist-packages/web/debugerror.py", line 337, in debugerror
    return web._InternalError(djangoerror())
  File "/usr/local/lib/python2.7/dist-packages/web/debugerror.py", line 315, in djangoerror
    djangoerror_r = Template(djangoerror_t, filename=__file__, filter=websafe)
  File "/usr/local/lib/python2.7/dist-packages/web/template.py", line 943, in __init__
    code = self.compile_template(text, filename)
  File "/usr/local/lib/python2.7/dist-packages/web/template.py", line 1020, in compile_template
    compiled_code = compile(code, filename, "exec")
  File "/usr/local/lib/python2.7/dist-packages/web/debugerror.pyc", line 8
    def with (exception_type, exception_value, frames)
           ^
SyntaxError: invalid syntax

Traceback (most recent call last):
  File "/usr/local/lib/python2.7/dist-packages/web/application.py", line 288, in process
    return p(lambda: process(processors))
  File "/usr/local/lib/python2.7/dist-packages/web/application.py", line 700, in processor
    return handler()
  File "/usr/local/lib/python2.7/dist-packages/web/application.py", line 288, in <lambda>
    return p(lambda: process(processors))
  File "/usr/local/lib/python2.7/dist-packages/web/application.py", line 297, in process
    raise self.internalerror()
  File "/usr/local/lib/python2.7/dist-packages/web/application.py", line 588, in internalerror
    return debugerror()
  File "/usr/local/lib/python2.7/dist-packages/web/debugerror.py", line 337, in debugerror
    return web._InternalError(djangoerror())
  File "/usr/local/lib/python2.7/dist-packages/web/debugerror.py", line 315, in djangoerror
    djangoerror_r = Template(djangoerror_t, filename=__file__, filter=websafe)
  File "/usr/local/lib/python2.7/dist-packages/web/template.py", line 943, in __init__
    code = self.compile_template(text, filename)
  File "/usr/local/lib/python2.7/dist-packages/web/template.py", line 1020, in compile_template
    compiled_code = compile(code, filename, "exec")
  File "/usr/local/lib/python2.7/dist-packages/web/debugerror.pyc", line 8
    def with (exception_type, exception_value, frames)
           ^
SyntaxError: invalid syntax

Traceback (most recent call last):
  File "/usr/local/lib/python2.7/dist-packages/web/application.py", line 329, in wsgi
    result = self.handle_with_processors()
  File "/usr/local/lib/python2.7/dist-packages/web/application.py", line 300, in handle_with_processors
    return process(self.processors)
  File "/usr/local/lib/python2.7/dist-packages/web/application.py", line 297, in process
    raise self.internalerror()
  File "/usr/local/lib/python2.7/dist-packages/web/application.py", line 588, in internalerror
    return debugerror()
  File "/usr/local/lib/python2.7/dist-packages/web/debugerror.py", line 337, in debugerror
    return web._InternalError(djangoerror())
  File "/usr/local/lib/python2.7/dist-packages/web/debugerror.py", line 315, in djangoerror
    djangoerror_r = Template(djangoerror_t, filename=__file__, filter=websafe)
  File "/usr/local/lib/python2.7/dist-packages/web/template.py", line 943, in __init__
    code = self.compile_template(text, filename)
  File "/usr/local/lib/python2.7/dist-packages/web/template.py", line 1020, in compile_template
    compiled_code = compile(code, filename, "exec")
  File "/usr/local/lib/python2.7/dist-packages/web/debugerror.pyc", line 8
    def with (exception_type, exception_value, frames)
           ^
SyntaxError: invalid syntax

Template traceback:
    File '/usr/local/lib/python2.7/dist-packages/web/debugerror.pyc', line 8
        None
[pid: 9971|app: 0|req: 11/11] 192.168.1.29 () {38 vars in 754 bytes} [Sun Jan 28 10:26:23 2024] GET / => generated 0 bytes in 42 msecs (HTTP/1.1 500) 0 headers in 0 bytes (0 switches on core 0)
Traceback (most recent call last):
  File "/usr/local/lib/python2.7/dist-packages/web/application.py", line 290, in process
    return self.handle()
  File "/usr/local/lib/python2.7/dist-packages/web/application.py", line 281, in handle
    return self._delegate(fn, self.fvars, args)
  File "/usr/local/lib/python2.7/dist-packages/web/application.py", line 531, in _delegate
    return handle_class(cls)
  File "/usr/local/lib/python2.7/dist-packages/web/application.py", line 509, in handle_class
    return tocall(*args)
TypeError: GET() takes exactly 2 arguments (1 given)

Traceback (most recent call last):
  File "/usr/local/lib/python2.7/dist-packages/web/application.py", line 288, in process
    return p(lambda: process(processors))
  File "/usr/local/lib/python2.7/dist-packages/web/application.py", line 700, in processor
    return handler()
  File "/usr/local/lib/python2.7/dist-packages/web/application.py", line 288, in <lambda>
    return p(lambda: process(processors))
  File "/usr/local/lib/python2.7/dist-packages/web/application.py", line 297, in process
    raise self.internalerror()
  File "/usr/local/lib/python2.7/dist-packages/web/application.py", line 588, in internalerror
    return debugerror()
  File "/usr/local/lib/python2.7/dist-packages/web/debugerror.py", line 337, in debugerror
    return web._InternalError(djangoerror())
  File "/usr/local/lib/python2.7/dist-packages/web/debugerror.py", line 315, in djangoerror
    djangoerror_r = Template(djangoerror_t, filename=__file__, filter=websafe)
  File "/usr/local/lib/python2.7/dist-packages/web/template.py", line 943, in __init__
    code = self.compile_template(text, filename)
  File "/usr/local/lib/python2.7/dist-packages/web/template.py", line 1020, in compile_template
    compiled_code = compile(code, filename, "exec")
  File "/usr/local/lib/python2.7/dist-packages/web/debugerror.pyc", line 8
    def with (exception_type, exception_value, frames)
           ^
SyntaxError: invalid syntax

Traceback (most recent call last):
  File "/usr/local/lib/python2.7/dist-packages/web/application.py", line 288, in process
    return p(lambda: process(processors))
  File "/usr/local/lib/python2.7/dist-packages/web/application.py", line 700, in processor
    return handler()
  File "/usr/local/lib/python2.7/dist-packages/web/application.py", line 288, in <lambda>
    return p(lambda: process(processors))
  File "/usr/local/lib/python2.7/dist-packages/web/application.py", line 297, in process
    raise self.internalerror()
  File "/usr/local/lib/python2.7/dist-packages/web/application.py", line 588, in internalerror
    return debugerror()
  File "/usr/local/lib/python2.7/dist-packages/web/debugerror.py", line 337, in debugerror
    return web._InternalError(djangoerror())
  File "/usr/local/lib/python2.7/dist-packages/web/debugerror.py", line 315, in djangoerror
    djangoerror_r = Template(djangoerror_t, filename=__file__, filter=websafe)
  File "/usr/local/lib/python2.7/dist-packages/web/template.py", line 943, in __init__
    code = self.compile_template(text, filename)
  File "/usr/local/lib/python2.7/dist-packages/web/template.py", line 1020, in compile_template
    compiled_code = compile(code, filename, "exec")
  File "/usr/local/lib/python2.7/dist-packages/web/debugerror.pyc", line 8
    def with (exception_type, exception_value, frames)
           ^
SyntaxError: invalid syntax

Traceback (most recent call last):
  File "/usr/local/lib/python2.7/dist-packages/web/application.py", line 288, in process
    return p(lambda: process(processors))
  File "/usr/local/lib/python2.7/dist-packages/web/application.py", line 717, in processor
    result = handler()
  File "/usr/local/lib/python2.7/dist-packages/web/application.py", line 288, in <lambda>
    return p(lambda: process(processors))
  File "/usr/local/lib/python2.7/dist-packages/web/application.py", line 297, in process
    raise self.internalerror()
  File "/usr/local/lib/python2.7/dist-packages/web/application.py", line 588, in internalerror
    return debugerror()
  File "/usr/local/lib/python2.7/dist-packages/web/debugerror.py", line 337, in debugerror
    return web._InternalError(djangoerror())
  File "/usr/local/lib/python2.7/dist-packages/web/debugerror.py", line 315, in djangoerror
    djangoerror_r = Template(djangoerror_t, filename=__file__, filter=websafe)
  File "/usr/local/lib/python2.7/dist-packages/web/template.py", line 943, in __init__
    code = self.compile_template(text, filename)
  File "/usr/local/lib/python2.7/dist-packages/web/template.py", line 1020, in compile_template
    compiled_code = compile(code, filename, "exec")
  File "/usr/local/lib/python2.7/dist-packages/web/debugerror.pyc", line 8
    def with (exception_type, exception_value, frames)
           ^
SyntaxError: invalid syntax

Traceback (most recent call last):
  File "/usr/local/lib/python2.7/dist-packages/web/application.py", line 288, in process
    return p(lambda: process(processors))
  File "/usr/local/lib/python2.7/dist-packages/web/application.py", line 700, in processor
    return handler()
  File "/usr/local/lib/python2.7/dist-packages/web/application.py", line 288, in <lambda>
    return p(lambda: process(processors))
  File "/usr/local/lib/python2.7/dist-packages/web/application.py", line 297, in process
    raise self.internalerror()
  File "/usr/local/lib/python2.7/dist-packages/web/application.py", line 588, in internalerror
    return debugerror()
  File "/usr/local/lib/python2.7/dist-packages/web/debugerror.py", line 337, in debugerror
    return web._InternalError(djangoerror())
  File "/usr/local/lib/python2.7/dist-packages/web/debugerror.py", line 315, in djangoerror
    djangoerror_r = Template(djangoerror_t, filename=__file__, filter=websafe)
  File "/usr/local/lib/python2.7/dist-packages/web/template.py", line 943, in __init__
    code = self.compile_template(text, filename)
  File "/usr/local/lib/python2.7/dist-packages/web/template.py", line 1020, in compile_template
    compiled_code = compile(code, filename, "exec")
  File "/usr/local/lib/python2.7/dist-packages/web/debugerror.pyc", line 8
    def with (exception_type, exception_value, frames)
           ^
SyntaxError: invalid syntax

Traceback (most recent call last):
  File "/usr/local/lib/python2.7/dist-packages/web/application.py", line 329, in wsgi
    result = self.handle_with_processors()
  File "/usr/local/lib/python2.7/dist-packages/web/application.py", line 300, in handle_with_processors
    return process(self.processors)
  File "/usr/local/lib/python2.7/dist-packages/web/application.py", line 297, in process
    raise self.internalerror()
  File "/usr/local/lib/python2.7/dist-packages/web/application.py", line 588, in internalerror
    return debugerror()
  File "/usr/local/lib/python2.7/dist-packages/web/debugerror.py", line 337, in debugerror
    return web._InternalError(djangoerror())
  File "/usr/local/lib/python2.7/dist-packages/web/debugerror.py", line 315, in djangoerror
    djangoerror_r = Template(djangoerror_t, filename=__file__, filter=websafe)
  File "/usr/local/lib/python2.7/dist-packages/web/template.py", line 943, in __init__
    code = self.compile_template(text, filename)
  File "/usr/local/lib/python2.7/dist-packages/web/template.py", line 1020, in compile_template
    compiled_code = compile(code, filename, "exec")
  File "/usr/local/lib/python2.7/dist-packages/web/debugerror.pyc", line 8
    def with (exception_type, exception_value, frames)
           ^
SyntaxError: invalid syntax

Template traceback:
    File '/usr/local/lib/python2.7/dist-packages/web/debugerror.pyc', line 8
        None
[pid: 9971|app: 0|req: 12/12] 192.168.1.29 () {38 vars in 754 bytes} [Sun Jan 28 10:26:23 2024] GET / => generated 0 bytes in 32 msecs (HTTP/1.1 500) 0 headers in 0 bytes (0 switches on core 0)
gateway "uWSGI http 1" has been buried (pid: 9972)
...gracefully killing workers...
Gracefully killing worker 1 (pid: 9971)...
worker 1 buried after 1 seconds
binary reloading uWSGI...
chdir() to /home/lz/demo/network/python/web
closing all non-uwsgi socket fds > 2 (max_fd = 1048576)...
found fd 3 mapped to socket 0 (127.0.0.1:34557)
running /usr/local/bin/uwsgi
[uWSGI] getting INI configuration from uwsgi.ini
*** Starting uWSGI 2.0.23 (64bit) on [Sun Jan 28 10:26:41 2024] ***
compiled with version: 7.5.0 on 28 January 2024 01:25:38
os: Linux-5.4.0-150-generic #167~18.04.1-Ubuntu SMP Wed May 24 00:51:42 UTC 2023
nodename: lz-virtual-machine
machine: x86_64
clock source: unix
detected number of CPU cores: 2
current working directory: /home/lz/demo/network/python/web
detected binary path: /usr/local/bin/uwsgi
!!! no internal routing support, rebuild with pcre support !!!
chdir() to /home/lz/demo/network/python/web
your processes number limit is 15400
your memory page size is 4096 bytes
detected max file descriptor number: 1048576
lock engine: pthread robust mutexes
thunder lock: disabled (you can enable it with --thunder-lock)
uWSGI http bound on 192.168.1.7:8000 fd 5
uwsgi socket 0 bound to TCP address 127.0.0.1:45705 (port auto-assigned) fd 4
Python version: 2.7.17 (default, Mar  8 2023, 18:40:28)  [GCC 7.5.0]
Python main interpreter initialized at 0x55cddf103180
python threads support enabled
your server socket listen backlog is limited to 100 connections
your mercy for graceful operations on workers is 60 seconds
mapped 203152 bytes (198 KB) for 1 cores
*** Operational MODE: single process ***
*** uWSGI is running in multiple interpreter mode ***
gracefully (RE)spawned uWSGI master process (pid: 9969)
spawned uWSGI worker 1 (pid: 10138, cores: 1)
spawned uWSGI http 1 (pid: 10139)
WSGI app 0 (mountpoint='') ready in 0 seconds on interpreter 0x55cddf103180 pid: 10138 (default app)
[pid: 10138|app: 0|req: 1/1] 192.168.1.29 () {38 vars in 754 bytes} [Sun Jan 28 10:26:48 2024] GET / => generated 8 bytes in 3 msecs (HTTP/1.1 200) 0 headers in 19 bytes (2 switches on core 0)
[pid: 10138|app: 0|req: 2/2] 192.168.1.29 () {36 vars in 679 bytes} [Sun Jan 28 10:26:48 2024] GET /favicon.ico => generated 14 bytes in 1 msecs (HTTP/1.1 200) 0 headers in 19 bytes (2 switches on core 0)
gateway "uWSGI http 1" has been buried (pid: 10139)
...gracefully killing workers...
Gracefully killing worker 1 (pid: 10138)...
worker 1 buried after 1 seconds
binary reloading uWSGI...
chdir() to /home/lz/demo/network/python/web
closing all non-uwsgi socket fds > 2 (max_fd = 1048576)...
found fd 4 mapped to socket 0 (127.0.0.1:45705)
running /usr/local/bin/uwsgi
[uWSGI] getting INI configuration from uwsgi.ini
*** Starting uWSGI 2.0.23 (64bit) on [Sun Jan 28 11:10:02 2024] ***
compiled with version: 7.5.0 on 28 January 2024 01:25:38
os: Linux-5.4.0-150-generic #167~18.04.1-Ubuntu SMP Wed May 24 00:51:42 UTC 2023
nodename: lz-virtual-machine
machine: x86_64
clock source: unix
detected number of CPU cores: 2
current working directory: /home/lz/demo/network/python/web
detected binary path: /usr/local/bin/uwsgi
!!! no internal routing support, rebuild with pcre support !!!
chdir() to /home/lz/demo/network/python/web
your processes number limit is 15400
your memory page size is 4096 bytes
detected max file descriptor number: 1048576
lock engine: pthread robust mutexes
thunder lock: disabled (you can enable it with --thunder-lock)
uWSGI http bound on 192.168.1.7:8000 fd 5
uwsgi socket 0 bound to TCP address 127.0.0.1:41169 (port auto-assigned) fd 3
Python version: 2.7.17 (default, Mar  8 2023, 18:40:28)  [GCC 7.5.0]
Python main interpreter initialized at 0x562858124180
python threads support enabled
your server socket listen backlog is limited to 100 connections
your mercy for graceful operations on workers is 60 seconds
mapped 203152 bytes (198 KB) for 1 cores
*** Operational MODE: single process ***
*** uWSGI is running in multiple interpreter mode ***
gracefully (RE)spawned uWSGI master process (pid: 9969)
spawned uWSGI worker 1 (pid: 14630, cores: 1)
spawned uWSGI http 1 (pid: 14631)
Traceback (most recent call last):
  File "1.py", line 17, in <module>
    db='web'
  File "/usr/local/lib/python2.7/dist-packages/web/db.py", line 1489, in database
    return _databases[dbn](**params)
  File "/usr/local/lib/python2.7/dist-packages/web/db.py", line 1253, in __init__
    db = import_driver(mysql_drivers, preferred=keywords.pop("driver", None))
  File "/usr/local/lib/python2.7/dist-packages/web/db.py", line 1299, in import_driver
    raise ImportError("Unable to import " + " or ".join(drivers))
ImportError: Unable to import MySQLdb or pymysql or mysql.connector
unable to load app 0 (mountpoint='') (callable not found or import error)
*** no app loaded. going in full dynamic mode ***
--- no python application found, check your startup logs for errors ---
[pid: 14630|app: -1|req: -1/1] 192.168.1.29 () {38 vars in 754 bytes} [Sun Jan 28 11:10:29 2024] GET / => generated 21 bytes in 0 msecs (HTTP/1.1 500) 2 headers in 83 bytes (0 switches on core 0)
--- no python application found, check your startup logs for errors ---
[pid: 14630|app: -1|req: -1/2] 192.168.1.29 () {36 vars in 679 bytes} [Sun Jan 28 11:10:30 2024] GET /favicon.ico => generated 21 bytes in 0 msecs (HTTP/1.1 500) 2 headers in 83 bytes (0 switches on core 0)
--- no python application found, check your startup logs for errors ---
[pid: 14630|app: -1|req: -1/3] 192.168.1.29 () {38 vars in 754 bytes} [Sun Jan 28 11:10:31 2024] GET / => generated 21 bytes in 0 msecs (HTTP/1.1 500) 2 headers in 83 bytes (0 switches on core 0)
--- no python application found, check your startup logs for errors ---
[pid: 14630|app: -1|req: -1/4] 192.168.1.29 () {36 vars in 679 bytes} [Sun Jan 28 11:10:32 2024] GET /favicon.ico => generated 21 bytes in 0 msecs (HTTP/1.1 500) 2 headers in 83 bytes (0 switches on core 0)
*** Starting uWSGI 2.0.23 (64bit) on [Sun Jan 28 11:11:54 2024] ***
compiled with version: 7.5.0 on 28 January 2024 01:25:38
os: Linux-5.4.0-150-generic #167~18.04.1-Ubuntu SMP Wed May 24 00:51:42 UTC 2023
nodename: lz-virtual-machine
machine: x86_64
clock source: unix
detected number of CPU cores: 2
current working directory: /home/lz/demo/network/python/web
writing pidfile to uwsgi.pidfile
detected binary path: /usr/local/bin/uwsgi
!!! no internal routing support, rebuild with pcre support !!!
chdir() to /home/lz/demo/network/python/web
your processes number limit is 15400
your memory page size is 4096 bytes
detected max file descriptor number: 1048576
lock engine: pthread robust mutexes
thunder lock: disabled (you can enable it with --thunder-lock)
probably another instance of uWSGI is running on the same address (192.168.1.7:8000).
bind(): Address already in use [core/socket.c line 769]
Sun Jan 28 11:13:43 2024 - uWSGI worker 1 screams: UAAAAAAH my master disconnected: i will kill myself !!!
*** Starting uWSGI 2.0.23 (64bit) on [Sun Jan 28 11:14:03 2024] ***
compiled with version: 7.5.0 on 28 January 2024 01:25:38
os: Linux-5.4.0-150-generic #167~18.04.1-Ubuntu SMP Wed May 24 00:51:42 UTC 2023
nodename: lz-virtual-machine
machine: x86_64
clock source: unix
detected number of CPU cores: 2
current working directory: /home/lz/demo/network/python/web
writing pidfile to uwsgi.pidfile
detected binary path: /usr/local/bin/uwsgi
!!! no internal routing support, rebuild with pcre support !!!
chdir() to /home/lz/demo/network/python/web
your processes number limit is 15400
your memory page size is 4096 bytes
detected max file descriptor number: 1048576
lock engine: pthread robust mutexes
thunder lock: disabled (you can enable it with --thunder-lock)
uWSGI http bound on 192.168.1.7:8000 fd 4
uwsgi socket 0 bound to TCP address 127.0.0.1:36529 (port auto-assigned) fd 3
Python version: 2.7.17 (default, Mar  8 2023, 18:40:28)  [GCC 7.5.0]
Python main interpreter initialized at 0x55f72d6bb3e0
python threads support enabled
your server socket listen backlog is limited to 100 connections
your mercy for graceful operations on workers is 60 seconds
mapped 203152 bytes (198 KB) for 1 cores
*** Operational MODE: single process ***
*** uWSGI is running in multiple interpreter mode ***
spawned uWSGI master process (pid: 15113)
spawned uWSGI worker 1 (pid: 15114, cores: 1)
spawned uWSGI http 1 (pid: 15115)
Traceback (most recent call last):
  File "1.py", line 17, in <module>
    db='web'
  File "/usr/local/lib/python2.7/dist-packages/web/db.py", line 1489, in database
    return _databases[dbn](**params)
  File "/usr/local/lib/python2.7/dist-packages/web/db.py", line 1253, in __init__
    db = import_driver(mysql_drivers, preferred=keywords.pop("driver", None))
  File "/usr/local/lib/python2.7/dist-packages/web/db.py", line 1299, in import_driver
    raise ImportError("Unable to import " + " or ".join(drivers))
ImportError: Unable to import MySQLdb or pymysql or mysql.connector
unable to load app 0 (mountpoint='') (callable not found or import error)
*** no app loaded. going in full dynamic mode ***
gateway "uWSGI http 1" has been buried (pid: 15115)
...gracefully killing workers...
Gracefully killing worker 1 (pid: 15114)...
worker 1 buried after 1 seconds
binary reloading uWSGI...
chdir() to /home/lz/demo/network/python/web
closing all non-uwsgi socket fds > 2 (max_fd = 1048576)...
found fd 3 mapped to socket 0 (127.0.0.1:36529)
running /usr/local/bin/uwsgi
[uWSGI] getting INI configuration from uwsgi.ini
*** Starting uWSGI 2.0.23 (64bit) on [Sun Jan 28 11:19:37 2024] ***
compiled with version: 7.5.0 on 28 January 2024 01:25:38
os: Linux-5.4.0-150-generic #167~18.04.1-Ubuntu SMP Wed May 24 00:51:42 UTC 2023
nodename: lz-virtual-machine
machine: x86_64
clock source: unix
detected number of CPU cores: 2
current working directory: /home/lz/demo/network/python/web
detected binary path: /usr/local/bin/uwsgi
!!! no internal routing support, rebuild with pcre support !!!
chdir() to /home/lz/demo/network/python/web
your processes number limit is 15400
your memory page size is 4096 bytes
detected max file descriptor number: 1048576
lock engine: pthread robust mutexes
thunder lock: disabled (you can enable it with --thunder-lock)
uWSGI http bound on 192.168.1.7:8000 fd 5
uwsgi socket 0 bound to TCP address 127.0.0.1:37817 (port auto-assigned) fd 4
Python version: 2.7.17 (default, Mar  8 2023, 18:40:28)  [GCC 7.5.0]
Python main interpreter initialized at 0x557e773e0180
python threads support enabled
your server socket listen backlog is limited to 100 connections
your mercy for graceful operations on workers is 60 seconds
mapped 203152 bytes (198 KB) for 1 cores
*** Operational MODE: single process ***
*** uWSGI is running in multiple interpreter mode ***
gracefully (RE)spawned uWSGI master process (pid: 15113)
spawned uWSGI worker 1 (pid: 15957, cores: 1)
spawned uWSGI http 1 (pid: 15958)
WSGI app 0 (mountpoint='') ready in 0 seconds on interpreter 0x557e773e0180 pid: 15957 (default app)
*** Starting uWSGI 2.0.23 (64bit) on [Tue Jan 30 10:00:08 2024] ***
compiled with version: 7.5.0 on 28 January 2024 01:25:38
os: Linux-5.4.0-150-generic #167~18.04.1-Ubuntu SMP Wed May 24 00:51:42 UTC 2023
nodename: lz-virtual-machine
machine: x86_64
clock source: unix
detected number of CPU cores: 2
current working directory: /home/lz/demo/network/python/web
writing pidfile to uwsgi.pidfile
detected binary path: /usr/local/bin/uwsgi
!!! no internal routing support, rebuild with pcre support !!!
chdir() to /home/lz/demo/network/python/web
your processes number limit is 15400
your memory page size is 4096 bytes
detected max file descriptor number: 1048576
lock engine: pthread robust mutexes
thunder lock: disabled (you can enable it with --thunder-lock)
bind(): Cannot assign requested address [core/socket.c line 769]
*** Starting uWSGI 2.0.23 (64bit) on [Tue Jan 30 10:10:57 2024] ***
compiled with version: 7.5.0 on 28 January 2024 01:25:38
os: Linux-5.4.0-150-generic #167~18.04.1-Ubuntu SMP Wed May 24 00:51:42 UTC 2023
nodename: lz-virtual-machine
machine: x86_64
clock source: unix
detected number of CPU cores: 2
current working directory: /home/lz/demo/network/python/web
writing pidfile to uwsgi.pidfile
detected binary path: /usr/local/bin/uwsgi
!!! no internal routing support, rebuild with pcre support !!!
chdir() to /home/lz/demo/network/python/web
your processes number limit is 15400
your memory page size is 4096 bytes
detected max file descriptor number: 1048576
lock engine: pthread robust mutexes
thunder lock: disabled (you can enable it with --thunder-lock)
uWSGI http bound on 192.168.6.150:8000 fd 4
uwsgi socket 0 bound to TCP address 127.0.0.1:33761 (port auto-assigned) fd 3
Python version: 2.7.17 (default, Mar  8 2023, 18:40:28)  [GCC 7.5.0]
Python main interpreter initialized at 0x56301086a3e0
python threads support enabled
your server socket listen backlog is limited to 100 connections
your mercy for graceful operations on workers is 60 seconds
mapped 203152 bytes (198 KB) for 1 cores
*** Operational MODE: single process ***
*** uWSGI is running in multiple interpreter mode ***
spawned uWSGI master process (pid: 11699)
spawned uWSGI worker 1 (pid: 11701, cores: 1)
spawned uWSGI http 1 (pid: 11702)
Traceback (most recent call last):
  File "1.py", line 3, in <module>
    import User_interface
  File "./User_interface.py", line 5
SyntaxError: Non-ASCII character '\xe5' in file ./User_interface.py on line 5, but no encoding declared; see http://python.org/dev/peps/pep-0263/ for details
unable to load app 0 (mountpoint='') (callable not found or import error)
*** no app loaded. going in full dynamic mode ***
gateway "uWSGI http 1" has been buried (pid: 11702)
...gracefully killing workers...
Gracefully killing worker 1 (pid: 11701)...
worker 1 buried after 1 seconds
binary reloading uWSGI...
chdir() to /home/lz/demo/network/python/web
closing all non-uwsgi socket fds > 2 (max_fd = 1048576)...
found fd 3 mapped to socket 0 (127.0.0.1:33761)
running /usr/local/bin/uwsgi
[uWSGI] getting INI configuration from uwsgi.ini
*** Starting uWSGI 2.0.23 (64bit) on [Tue Jan 30 10:11:07 2024] ***
compiled with version: 7.5.0 on 28 January 2024 01:25:38
os: Linux-5.4.0-150-generic #167~18.04.1-Ubuntu SMP Wed May 24 00:51:42 UTC 2023
nodename: lz-virtual-machine
machine: x86_64
clock source: unix
detected number of CPU cores: 2
current working directory: /home/lz/demo/network/python/web
detected binary path: /usr/local/bin/uwsgi
!!! no internal routing support, rebuild with pcre support !!!
chdir() to /home/lz/demo/network/python/web
your processes number limit is 15400
your memory page size is 4096 bytes
detected max file descriptor number: 1048576
lock engine: pthread robust mutexes
thunder lock: disabled (you can enable it with --thunder-lock)
uWSGI http bound on 192.168.6.150:8000 fd 5
uwsgi socket 0 bound to TCP address 127.0.0.1:41629 (port auto-assigned) fd 4
Python version: 2.7.17 (default, Mar  8 2023, 18:40:28)  [GCC 7.5.0]
Python main interpreter initialized at 0x5646ebfd0180
python threads support enabled
your server socket listen backlog is limited to 100 connections
your mercy for graceful operations on workers is 60 seconds
mapped 203152 bytes (198 KB) for 1 cores
*** Operational MODE: single process ***
*** uWSGI is running in multiple interpreter mode ***
gracefully (RE)spawned uWSGI master process (pid: 11699)
spawned uWSGI worker 1 (pid: 11772, cores: 1)
spawned uWSGI http 1 (pid: 11773)
Traceback (most recent call last):
  File "1.py", line 3, in <module>
    import User_interface
  File "./User_interface.py", line 5
SyntaxError: Non-ASCII character '\xe5' in file ./User_interface.py on line 5, but no encoding declared; see http://python.org/dev/peps/pep-0263/ for details
unable to load app 0 (mountpoint='') (callable not found or import error)
*** no app loaded. going in full dynamic mode ***
gateway "uWSGI http 1" has been buried (pid: 11773)
...gracefully killing workers...
Gracefully killing worker 1 (pid: 11772)...
worker 1 buried after 1 seconds
binary reloading uWSGI...
chdir() to /home/lz/demo/network/python/web
closing all non-uwsgi socket fds > 2 (max_fd = 1048576)...
found fd 4 mapped to socket 0 (127.0.0.1:41629)
running /usr/local/bin/uwsgi
[uWSGI] getting INI configuration from uwsgi.ini
*** Starting uWSGI 2.0.23 (64bit) on [Tue Jan 30 10:33:03 2024] ***
compiled with version: 7.5.0 on 28 January 2024 01:25:38
os: Linux-5.4.0-150-generic #167~18.04.1-Ubuntu SMP Wed May 24 00:51:42 UTC 2023
nodename: lz-virtual-machine
machine: x86_64
clock source: unix
detected number of CPU cores: 2
current working directory: /home/lz/demo/network/python/web
detected binary path: /usr/local/bin/uwsgi
!!! no internal routing support, rebuild with pcre support !!!
chdir() to /home/lz/demo/network/python/web
your processes number limit is 15400
your memory page size is 4096 bytes
detected max file descriptor number: 1048576
lock engine: pthread robust mutexes
thunder lock: disabled (you can enable it with --thunder-lock)
uWSGI http bound on 192.168.6.150:8000 fd 5
uwsgi socket 0 bound to TCP address 127.0.0.1:37453 (port auto-assigned) fd 3
Python version: 2.7.17 (default, Mar  8 2023, 18:40:28)  [GCC 7.5.0]
Python main interpreter initialized at 0x5600be566180
python threads support enabled
your server socket listen backlog is limited to 100 connections
your mercy for graceful operations on workers is 60 seconds
mapped 203152 bytes (198 KB) for 1 cores
*** Operational MODE: single process ***
*** uWSGI is running in multiple interpreter mode ***
gracefully (RE)spawned uWSGI master process (pid: 11699)
spawned uWSGI worker 1 (pid: 12540, cores: 1)
spawned uWSGI http 1 (pid: 12541)
Traceback (most recent call last):
  File "1.py", line 3, in <module>
    import User_interface
  File "./User_interface.py", line 5
SyntaxError: Non-ASCII character '\xe5' in file ./User_interface.py on line 5, but no encoding declared; see http://python.org/dev/peps/pep-0263/ for details
unable to load app 0 (mountpoint='') (callable not found or import error)
*** no app loaded. going in full dynamic mode ***
gateway "uWSGI http 1" has been buried (pid: 12541)
...gracefully killing workers...
Gracefully killing worker 1 (pid: 12540)...
worker 1 buried after 1 seconds
binary reloading uWSGI...
chdir() to /home/lz/demo/network/python/web
closing all non-uwsgi socket fds > 2 (max_fd = 1048576)...
found fd 3 mapped to socket 0 (127.0.0.1:37453)
running /usr/local/bin/uwsgi
[uWSGI] getting INI configuration from uwsgi.ini
*** Starting uWSGI 2.0.23 (64bit) on [Tue Jan 30 10:35:17 2024] ***
compiled with version: 7.5.0 on 28 January 2024 01:25:38
os: Linux-5.4.0-150-generic #167~18.04.1-Ubuntu SMP Wed May 24 00:51:42 UTC 2023
nodename: lz-virtual-machine
machine: x86_64
clock source: unix
detected number of CPU cores: 2
current working directory: /home/lz/demo/network/python/web
detected binary path: /usr/local/bin/uwsgi
!!! no internal routing support, rebuild with pcre support !!!
chdir() to /home/lz/demo/network/python/web
your processes number limit is 15400
your memory page size is 4096 bytes
detected max file descriptor number: 1048576
lock engine: pthread robust mutexes
thunder lock: disabled (you can enable it with --thunder-lock)
uWSGI http bound on 192.168.6.150:8000 fd 5
uwsgi socket 0 bound to TCP address 127.0.0.1:45051 (port auto-assigned) fd 4
Python version: 2.7.17 (default, Mar  8 2023, 18:40:28)  [GCC 7.5.0]
Python main interpreter initialized at 0x5584c70ca180
python threads support enabled
your server socket listen backlog is limited to 100 connections
your mercy for graceful operations on workers is 60 seconds
mapped 203152 bytes (198 KB) for 1 cores
*** Operational MODE: single process ***
*** uWSGI is running in multiple interpreter mode ***
gracefully (RE)spawned uWSGI master process (pid: 11699)
spawned uWSGI worker 1 (pid: 12625, cores: 1)
spawned uWSGI http 1 (pid: 12626)
Traceback (most recent call last):
  File "1.py", line 3, in <module>
    import User_interface
  File "./User_interface.py", line 5
SyntaxError: Non-ASCII character '\xe5' in file ./User_interface.py on line 5, but no encoding declared; see http://python.org/dev/peps/pep-0263/ for details
unable to load app 0 (mountpoint='') (callable not found or import error)
*** no app loaded. going in full dynamic mode ***
gateway "uWSGI http 1" has been buried (pid: 12626)
...gracefully killing workers...
Gracefully killing worker 1 (pid: 12625)...
worker 1 buried after 1 seconds
binary reloading uWSGI...
chdir() to /home/lz/demo/network/python/web
closing all non-uwsgi socket fds > 2 (max_fd = 1048576)...
found fd 4 mapped to socket 0 (127.0.0.1:45051)
running /usr/local/bin/uwsgi
[uWSGI] getting INI configuration from uwsgi.ini
*** Starting uWSGI 2.0.23 (64bit) on [Tue Jan 30 10:38:23 2024] ***
compiled with version: 7.5.0 on 28 January 2024 01:25:38
os: Linux-5.4.0-150-generic #167~18.04.1-Ubuntu SMP Wed May 24 00:51:42 UTC 2023
nodename: lz-virtual-machine
machine: x86_64
clock source: unix
detected number of CPU cores: 2
current working directory: /home/lz/demo/network/python/web
detected binary path: /usr/local/bin/uwsgi
!!! no internal routing support, rebuild with pcre support !!!
chdir() to /home/lz/demo/network/python/web
your processes number limit is 15400
your memory page size is 4096 bytes
detected max file descriptor number: 1048576
lock engine: pthread robust mutexes
thunder lock: disabled (you can enable it with --thunder-lock)
uWSGI http bound on 192.168.6.150:8000 fd 5
uwsgi socket 0 bound to TCP address 127.0.0.1:42391 (port auto-assigned) fd 3
Python version: 2.7.17 (default, Mar  8 2023, 18:40:28)  [GCC 7.5.0]
Python main interpreter initialized at 0x556ab5907180
python threads support enabled
your server socket listen backlog is limited to 100 connections
your mercy for graceful operations on workers is 60 seconds
mapped 203152 bytes (198 KB) for 1 cores
*** Operational MODE: single process ***
*** uWSGI is running in multiple interpreter mode ***
gracefully (RE)spawned uWSGI master process (pid: 11699)
spawned uWSGI worker 1 (pid: 12746, cores: 1)
spawned uWSGI http 1 (pid: 12747)
Traceback (most recent call last):
  File "1.py", line 3, in <module>
    import User_interface
  File "./User_interface.py", line 10
    def IS_Phone_Number(phone: Union[str, int]) -> bool:
                             ^
SyntaxError: invalid syntax
unable to load app 0 (mountpoint='') (callable not found or import error)
*** no app loaded. going in full dynamic mode ***
gateway "uWSGI http 1" has been buried (pid: 12747)
...gracefully killing workers...
Gracefully killing worker 1 (pid: 12746)...
worker 1 buried after 1 seconds
binary reloading uWSGI...
chdir() to /home/lz/demo/network/python/web
closing all non-uwsgi socket fds > 2 (max_fd = 1048576)...
found fd 3 mapped to socket 0 (127.0.0.1:42391)
running /usr/local/bin/uwsgi
[uWSGI] getting INI configuration from uwsgi.ini
*** Starting uWSGI 2.0.23 (64bit) on [Tue Jan 30 10:38:31 2024] ***
compiled with version: 7.5.0 on 28 January 2024 01:25:38
os: Linux-5.4.0-150-generic #167~18.04.1-Ubuntu SMP Wed May 24 00:51:42 UTC 2023
nodename: lz-virtual-machine
machine: x86_64
clock source: unix
detected number of CPU cores: 2
current working directory: /home/lz/demo/network/python/web
detected binary path: /usr/local/bin/uwsgi
!!! no internal routing support, rebuild with pcre support !!!
chdir() to /home/lz/demo/network/python/web
your processes number limit is 15400
your memory page size is 4096 bytes
detected max file descriptor number: 1048576
lock engine: pthread robust mutexes
thunder lock: disabled (you can enable it with --thunder-lock)
uWSGI http bound on 192.168.6.150:8000 fd 5
uwsgi socket 0 bound to TCP address 127.0.0.1:36759 (port auto-assigned) fd 4
Python version: 2.7.17 (default, Mar  8 2023, 18:40:28)  [GCC 7.5.0]
Python main interpreter initialized at 0x562a75400180
python threads support enabled
your server socket listen backlog is limited to 100 connections
your mercy for graceful operations on workers is 60 seconds
mapped 203152 bytes (198 KB) for 1 cores
*** Operational MODE: single process ***
*** uWSGI is running in multiple interpreter mode ***
gracefully (RE)spawned uWSGI master process (pid: 11699)
spawned uWSGI worker 1 (pid: 12787, cores: 1)
spawned uWSGI http 1 (pid: 12788)
Traceback (most recent call last):
  File "1.py", line 3, in <module>
    import User_interface
  File "./User_interface.py", line 10
    def IS_Phone_Number(phone: Union[str, int]) -> bool:
                             ^
SyntaxError: invalid syntax
unable to load app 0 (mountpoint='') (callable not found or import error)
*** no app loaded. going in full dynamic mode ***
gateway "uWSGI http 1" has been buried (pid: 12788)
...gracefully killing workers...
Gracefully killing worker 1 (pid: 12787)...
worker 1 buried after 1 seconds
binary reloading uWSGI...
chdir() to /home/lz/demo/network/python/web
closing all non-uwsgi socket fds > 2 (max_fd = 1048576)...
found fd 4 mapped to socket 0 (127.0.0.1:36759)
running /usr/local/bin/uwsgi
[uWSGI] getting INI configuration from uwsgi.ini
*** Starting uWSGI 2.0.23 (64bit) on [Tue Jan 30 10:39:11 2024] ***
compiled with version: 7.5.0 on 28 January 2024 01:25:38
os: Linux-5.4.0-150-generic #167~18.04.1-Ubuntu SMP Wed May 24 00:51:42 UTC 2023
nodename: lz-virtual-machine
machine: x86_64
clock source: unix
detected number of CPU cores: 2
current working directory: /home/lz/demo/network/python/web
detected binary path: /usr/local/bin/uwsgi
!!! no internal routing support, rebuild with pcre support !!!
chdir() to /home/lz/demo/network/python/web
your processes number limit is 15400
your memory page size is 4096 bytes
detected max file descriptor number: 1048576
lock engine: pthread robust mutexes
thunder lock: disabled (you can enable it with --thunder-lock)
uWSGI http bound on 192.168.6.150:8000 fd 5
uwsgi socket 0 bound to TCP address 127.0.0.1:45549 (port auto-assigned) fd 3
Python version: 2.7.17 (default, Mar  8 2023, 18:40:28)  [GCC 7.5.0]
Python main interpreter initialized at 0x559a03940180
python threads support enabled
your server socket listen backlog is limited to 100 connections
your mercy for graceful operations on workers is 60 seconds
mapped 203152 bytes (198 KB) for 1 cores
*** Operational MODE: single process ***
*** uWSGI is running in multiple interpreter mode ***
gracefully (RE)spawned uWSGI master process (pid: 11699)
spawned uWSGI worker 1 (pid: 12845, cores: 1)
spawned uWSGI http 1 (pid: 12846)
Traceback (most recent call last):
  File "1.py", line 7, in <module>
    import User_interface
  File "./User_interface.py", line 10
    def IS_Phone_Number(phone: Union[str, int]) -> bool:
                             ^
SyntaxError: invalid syntax
unable to load app 0 (mountpoint='') (callable not found or import error)
*** no app loaded. going in full dynamic mode ***
gateway "uWSGI http 1" has been buried (pid: 12846)
...gracefully killing workers...
Gracefully killing worker 1 (pid: 12845)...
worker 1 buried after 1 seconds
binary reloading uWSGI...
chdir() to /home/lz/demo/network/python/web
closing all non-uwsgi socket fds > 2 (max_fd = 1048576)...
found fd 3 mapped to socket 0 (127.0.0.1:45549)
running /usr/local/bin/uwsgi
[uWSGI] getting INI configuration from uwsgi.ini
*** Starting uWSGI 2.0.23 (64bit) on [Tue Jan 30 10:39:51 2024] ***
compiled with version: 7.5.0 on 28 January 2024 01:25:38
os: Linux-5.4.0-150-generic #167~18.04.1-Ubuntu SMP Wed May 24 00:51:42 UTC 2023
nodename: lz-virtual-machine
machine: x86_64
clock source: unix
detected number of CPU cores: 2
current working directory: /home/lz/demo/network/python/web
detected binary path: /usr/local/bin/uwsgi
!!! no internal routing support, rebuild with pcre support !!!
chdir() to /home/lz/demo/network/python/web
your processes number limit is 15400
your memory page size is 4096 bytes
detected max file descriptor number: 1048576
lock engine: pthread robust mutexes
thunder lock: disabled (you can enable it with --thunder-lock)
uWSGI http bound on 192.168.6.150:8000 fd 5
uwsgi socket 0 bound to TCP address 127.0.0.1:37005 (port auto-assigned) fd 4
Python version: 2.7.17 (default, Mar  8 2023, 18:40:28)  [GCC 7.5.0]
Python main interpreter initialized at 0x555a77b79180
python threads support enabled
your server socket listen backlog is limited to 100 connections
your mercy for graceful operations on workers is 60 seconds
mapped 203152 bytes (198 KB) for 1 cores
*** Operational MODE: single process ***
*** uWSGI is running in multiple interpreter mode ***
gracefully (RE)spawned uWSGI master process (pid: 11699)
spawned uWSGI worker 1 (pid: 12899, cores: 1)
spawned uWSGI http 1 (pid: 12900)
Traceback (most recent call last):
  File "1.py", line 7, in <module>
    import User_interface
  File "./User_interface.py", line 10
    def IS_Phone_Number(phone) -> bool:
                               ^
SyntaxError: invalid syntax
unable to load app 0 (mountpoint='') (callable not found or import error)
*** no app loaded. going in full dynamic mode ***
gateway "uWSGI http 1" has been buried (pid: 12900)
...gracefully killing workers...
Gracefully killing worker 1 (pid: 12899)...
worker 1 buried after 1 seconds
binary reloading uWSGI...
chdir() to /home/lz/demo/network/python/web
closing all non-uwsgi socket fds > 2 (max_fd = 1048576)...
found fd 4 mapped to socket 0 (127.0.0.1:37005)
running /usr/local/bin/uwsgi
[uWSGI] getting INI configuration from uwsgi.ini
*** Starting uWSGI 2.0.23 (64bit) on [Tue Jan 30 10:40:35 2024] ***
compiled with version: 7.5.0 on 28 January 2024 01:25:38
os: Linux-5.4.0-150-generic #167~18.04.1-Ubuntu SMP Wed May 24 00:51:42 UTC 2023
nodename: lz-virtual-machine
machine: x86_64
clock source: unix
detected number of CPU cores: 2
current working directory: /home/lz/demo/network/python/web
detected binary path: /usr/local/bin/uwsgi
!!! no internal routing support, rebuild with pcre support !!!
chdir() to /home/lz/demo/network/python/web
your processes number limit is 15400
your memory page size is 4096 bytes
detected max file descriptor number: 1048576
lock engine: pthread robust mutexes
thunder lock: disabled (you can enable it with --thunder-lock)
uWSGI http bound on 192.168.6.150:8000 fd 5
uwsgi socket 0 bound to TCP address 127.0.0.1:39037 (port auto-assigned) fd 3
Python version: 2.7.17 (default, Mar  8 2023, 18:40:28)  [GCC 7.5.0]
Python main interpreter initialized at 0x56203aa9f180
python threads support enabled
your server socket listen backlog is limited to 100 connections
your mercy for graceful operations on workers is 60 seconds
mapped 203152 bytes (198 KB) for 1 cores
*** Operational MODE: single process ***
*** uWSGI is running in multiple interpreter mode ***
gracefully (RE)spawned uWSGI master process (pid: 11699)
spawned uWSGI worker 1 (pid: 12961, cores: 1)
spawned uWSGI http 1 (pid: 12962)
Traceback (most recent call last):
  File "1.py", line 7, in <module>
    import User_interface
  File "./User_interface.py", line 7, in <module>
    from typing import Union
ImportError: No module named typing
unable to load app 0 (mountpoint='') (callable not found or import error)
*** no app loaded. going in full dynamic mode ***
gateway "uWSGI http 1" has been buried (pid: 12962)
...gracefully killing workers...
Gracefully killing worker 1 (pid: 12961)...
worker 1 buried after 1 seconds
binary reloading uWSGI...
chdir() to /home/lz/demo/network/python/web
closing all non-uwsgi socket fds > 2 (max_fd = 1048576)...
found fd 3 mapped to socket 0 (127.0.0.1:39037)
running /usr/local/bin/uwsgi
[uWSGI] getting INI configuration from uwsgi.ini
*** Starting uWSGI 2.0.23 (64bit) on [Tue Jan 30 10:41:06 2024] ***
compiled with version: 7.5.0 on 28 January 2024 01:25:38
os: Linux-5.4.0-150-generic #167~18.04.1-Ubuntu SMP Wed May 24 00:51:42 UTC 2023
nodename: lz-virtual-machine
machine: x86_64
clock source: unix
detected number of CPU cores: 2
current working directory: /home/lz/demo/network/python/web
detected binary path: /usr/local/bin/uwsgi
!!! no internal routing support, rebuild with pcre support !!!
chdir() to /home/lz/demo/network/python/web
your processes number limit is 15400
your memory page size is 4096 bytes
detected max file descriptor number: 1048576
lock engine: pthread robust mutexes
thunder lock: disabled (you can enable it with --thunder-lock)
uWSGI http bound on 192.168.6.150:8000 fd 5
uwsgi socket 0 bound to TCP address 127.0.0.1:45679 (port auto-assigned) fd 4
Python version: 2.7.17 (default, Mar  8 2023, 18:40:28)  [GCC 7.5.0]
Python main interpreter initialized at 0x55f0a7a19180
python threads support enabled
your server socket listen backlog is limited to 100 connections
your mercy for graceful operations on workers is 60 seconds
mapped 203152 bytes (198 KB) for 1 cores
*** Operational MODE: single process ***
*** uWSGI is running in multiple interpreter mode ***
gracefully (RE)spawned uWSGI master process (pid: 11699)
spawned uWSGI worker 1 (pid: 13011, cores: 1)
spawned uWSGI http 1 (pid: 13012)
Traceback (most recent call last):
  File "1.py", line 39, in <module>
    gdb.insert('user',password='123456',secpassword ='123456',nike='haha',phonenum='123',idcard='001',createtime=datetime.now(),lastlogintime=datetime.now())
  File "/usr/local/lib/python2.7/dist-packages/web/db.py", line 1008, in insert
    db_cursor = self._db_cursor()
  File "/usr/local/lib/python2.7/dist-packages/web/db.py", line 750, in _db_cursor
    return self.ctx.db.cursor()
  File "/usr/local/lib/python2.7/dist-packages/web/db.py", line 690, in _getctx
    self._load_context(self._ctx)
  File "/usr/local/lib/python2.7/dist-packages/web/db.py", line 702, in _load_context
    ctx.db = self._connect(self.keywords)
  File "/usr/local/lib/python2.7/dist-packages/web/db.py", line 730, in _connect
    return self.db_module.connect(**keywords)
  File "/usr/lib/python2.7/dist-packages/MySQLdb/__init__.py", line 86, in Connect
    return Connection(*args, **kwargs)
  File "/usr/lib/python2.7/dist-packages/MySQLdb/connections.py", line 204, in __init__
    super(Connection, self).__init__(*args, **kwargs2)
TypeError: an integer is required
unable to load app 0 (mountpoint='') (callable not found or import error)
*** no app loaded. going in full dynamic mode ***
gateway "uWSGI http 1" has been buried (pid: 13012)
...gracefully killing workers...
Gracefully killing worker 1 (pid: 13011)...
worker 1 buried after 1 seconds
binary reloading uWSGI...
chdir() to /home/lz/demo/network/python/web
closing all non-uwsgi socket fds > 2 (max_fd = 1048576)...
found fd 4 mapped to socket 0 (127.0.0.1:45679)
running /usr/local/bin/uwsgi
[uWSGI] getting INI configuration from uwsgi.ini
*** Starting uWSGI 2.0.23 (64bit) on [Tue Jan 30 10:44:15 2024] ***
compiled with version: 7.5.0 on 28 January 2024 01:25:38
os: Linux-5.4.0-150-generic #167~18.04.1-Ubuntu SMP Wed May 24 00:51:42 UTC 2023
nodename: lz-virtual-machine
machine: x86_64
clock source: unix
detected number of CPU cores: 2
current working directory: /home/lz/demo/network/python/web
detected binary path: /usr/local/bin/uwsgi
!!! no internal routing support, rebuild with pcre support !!!
chdir() to /home/lz/demo/network/python/web
your processes number limit is 15400
your memory page size is 4096 bytes
detected max file descriptor number: 1048576
lock engine: pthread robust mutexes
thunder lock: disabled (you can enable it with --thunder-lock)
uWSGI http bound on 192.168.6.150:8000 fd 5
uwsgi socket 0 bound to TCP address 127.0.0.1:44777 (port auto-assigned) fd 3
Python version: 2.7.17 (default, Mar  8 2023, 18:40:28)  [GCC 7.5.0]
Python main interpreter initialized at 0x55e25e512180
python threads support enabled
your server socket listen backlog is limited to 100 connections
your mercy for graceful operations on workers is 60 seconds
mapped 203152 bytes (198 KB) for 1 cores
*** Operational MODE: single process ***
*** uWSGI is running in multiple interpreter mode ***
gracefully (RE)spawned uWSGI master process (pid: 11699)
spawned uWSGI worker 1 (pid: 13178, cores: 1)
spawned uWSGI http 1 (pid: 13179)
Traceback (most recent call last):
  File "1.py", line 39, in <module>
    gdb.insert('user',password='123456',secpassword ='123456',nike='haha',phonenum='123',idcard='001',createtime=datetime.now(),lastlogintime=datetime.now())
  File "/usr/local/lib/python2.7/dist-packages/web/db.py", line 1008, in insert
    db_cursor = self._db_cursor()
  File "/usr/local/lib/python2.7/dist-packages/web/db.py", line 750, in _db_cursor
    return self.ctx.db.cursor()
  File "/usr/local/lib/python2.7/dist-packages/web/db.py", line 690, in _getctx
    self._load_context(self._ctx)
  File "/usr/local/lib/python2.7/dist-packages/web/db.py", line 702, in _load_context
    ctx.db = self._connect(self.keywords)
  File "/usr/local/lib/python2.7/dist-packages/web/db.py", line 730, in _connect
    return self.db_module.connect(**keywords)
  File "/usr/lib/python2.7/dist-packages/MySQLdb/__init__.py", line 86, in Connect
    return Connection(*args, **kwargs)
  File "/usr/lib/python2.7/dist-packages/MySQLdb/connections.py", line 204, in __init__
    super(Connection, self).__init__(*args, **kwargs2)
TypeError: an integer is required
unable to load app 0 (mountpoint='') (callable not found or import error)
*** no app loaded. going in full dynamic mode ***
gateway "uWSGI http 1" has been buried (pid: 13179)
...gracefully killing workers...
Gracefully killing worker 1 (pid: 13178)...
worker 1 buried after 1 seconds
binary reloading uWSGI...
chdir() to /home/lz/demo/network/python/web
closing all non-uwsgi socket fds > 2 (max_fd = 1048576)...
found fd 3 mapped to socket 0 (127.0.0.1:44777)
running /usr/local/bin/uwsgi
[uWSGI] getting INI configuration from uwsgi.ini
*** Starting uWSGI 2.0.23 (64bit) on [Tue Jan 30 11:50:29 2024] ***
compiled with version: 7.5.0 on 28 January 2024 01:25:38
os: Linux-5.4.0-150-generic #167~18.04.1-Ubuntu SMP Wed May 24 00:51:42 UTC 2023
nodename: lz-virtual-machine
machine: x86_64
clock source: unix
detected number of CPU cores: 2
current working directory: /home/lz/demo/network/python/web
detected binary path: /usr/local/bin/uwsgi
!!! no internal routing support, rebuild with pcre support !!!
chdir() to /home/lz/demo/network/python/web
your processes number limit is 15400
your memory page size is 4096 bytes
detected max file descriptor number: 1048576
lock engine: pthread robust mutexes
thunder lock: disabled (you can enable it with --thunder-lock)
uWSGI http bound on 192.168.6.150:8000 fd 5
uwsgi socket 0 bound to TCP address 127.0.0.1:46785 (port auto-assigned) fd 4
Python version: 2.7.17 (default, Mar  8 2023, 18:40:28)  [GCC 7.5.0]
Python main interpreter initialized at 0x559f767c8180
python threads support enabled
your server socket listen backlog is limited to 100 connections
your mercy for graceful operations on workers is 60 seconds
mapped 203152 bytes (198 KB) for 1 cores
*** Operational MODE: single process ***
*** uWSGI is running in multiple interpreter mode ***
gracefully (RE)spawned uWSGI master process (pid: 11699)
spawned uWSGI worker 1 (pid: 14454, cores: 1)
spawned uWSGI http 1 (pid: 14455)
Traceback (most recent call last):
  File "1.py", line 35, in <module>
    gdb.insert('user',password='123456',secpassword ='123456',nike='haha',phonenum='123',idcard='001',createtime=datetime.now(),lastlogintime=datetime.now())
  File "/usr/local/lib/python2.7/dist-packages/web/db.py", line 1008, in insert
    db_cursor = self._db_cursor()
  File "/usr/local/lib/python2.7/dist-packages/web/db.py", line 750, in _db_cursor
    return self.ctx.db.cursor()
  File "/usr/local/lib/python2.7/dist-packages/web/db.py", line 690, in _getctx
    self._load_context(self._ctx)
  File "/usr/local/lib/python2.7/dist-packages/web/db.py", line 702, in _load_context
    ctx.db = self._connect(self.keywords)
  File "/usr/local/lib/python2.7/dist-packages/web/db.py", line 730, in _connect
    return self.db_module.connect(**keywords)
  File "/usr/lib/python2.7/dist-packages/MySQLdb/__init__.py", line 86, in Connect
    return Connection(*args, **kwargs)
  File "/usr/lib/python2.7/dist-packages/MySQLdb/connections.py", line 204, in __init__
    super(Connection, self).__init__(*args, **kwargs2)
TypeError: an integer is required
unable to load app 0 (mountpoint='') (callable not found or import error)
*** no app loaded. going in full dynamic mode ***
gateway "uWSGI http 1" has been buried (pid: 14455)
...gracefully killing workers...
Gracefully killing worker 1 (pid: 14454)...
worker 1 buried after 1 seconds
binary reloading uWSGI...
chdir() to /home/lz/demo/network/python/web
closing all non-uwsgi socket fds > 2 (max_fd = 1048576)...
found fd 4 mapped to socket 0 (127.0.0.1:46785)
running /usr/local/bin/uwsgi
[uWSGI] getting INI configuration from uwsgi.ini
*** Starting uWSGI 2.0.23 (64bit) on [Tue Jan 30 12:03:07 2024] ***
compiled with version: 7.5.0 on 28 January 2024 01:25:38
os: Linux-5.4.0-150-generic #167~18.04.1-Ubuntu SMP Wed May 24 00:51:42 UTC 2023
nodename: lz-virtual-machine
machine: x86_64
clock source: unix
detected number of CPU cores: 2
current working directory: /home/lz/demo/network/python/web
detected binary path: /usr/local/bin/uwsgi
!!! no internal routing support, rebuild with pcre support !!!
chdir() to /home/lz/demo/network/python/web
your processes number limit is 15400
your memory page size is 4096 bytes
detected max file descriptor number: 1048576
lock engine: pthread robust mutexes
thunder lock: disabled (you can enable it with --thunder-lock)
uWSGI http bound on 192.168.6.150:8000 fd 5
uwsgi socket 0 bound to TCP address 127.0.0.1:39449 (port auto-assigned) fd 3
Python version: 2.7.17 (default, Mar  8 2023, 18:40:28)  [GCC 7.5.0]
Python main interpreter initialized at 0x561c3183d180
python threads support enabled
your server socket listen backlog is limited to 100 connections
your mercy for graceful operations on workers is 60 seconds
mapped 203152 bytes (198 KB) for 1 cores
*** Operational MODE: single process ***
*** uWSGI is running in multiple interpreter mode ***
gracefully (RE)spawned uWSGI master process (pid: 11699)
spawned uWSGI worker 1 (pid: 14742, cores: 1)
spawned uWSGI http 1 (pid: 14743)
Traceback (most recent call last):
  File "1.py", line 35, in <module>
    gdb.insert('user',password='123456',secpassword ='123456',nike='haha',phonenum='123',idcard='001',createtime=datetime.now(),lastlogintime=datetime.now())
  File "/usr/local/lib/python2.7/dist-packages/web/db.py", line 1008, in insert
    db_cursor = self._db_cursor()
  File "/usr/local/lib/python2.7/dist-packages/web/db.py", line 750, in _db_cursor
    return self.ctx.db.cursor()
  File "/usr/local/lib/python2.7/dist-packages/web/db.py", line 690, in _getctx
    self._load_context(self._ctx)
  File "/usr/local/lib/python2.7/dist-packages/web/db.py", line 702, in _load_context
    ctx.db = self._connect(self.keywords)
  File "/usr/local/lib/python2.7/dist-packages/web/db.py", line 730, in _connect
    return self.db_module.connect(**keywords)
  File "/usr/lib/python2.7/dist-packages/MySQLdb/__init__.py", line 86, in Connect
    return Connection(*args, **kwargs)
  File "/usr/lib/python2.7/dist-packages/MySQLdb/connections.py", line 204, in __init__
    super(Connection, self).__init__(*args, **kwargs2)
TypeError: an integer is required
unable to load app 0 (mountpoint='') (callable not found or import error)
*** no app loaded. going in full dynamic mode ***
